Workbook

Sheet Nombre Equipo
C3: Integrantes del equipo
C4: 1
C5: =+C4+1 -> 2
C6: =+C5+1 -> 3
C7: =+C6+1 -> 4
C8: =+C7+1 -> 5
C9: =+C8+1 -> 6
C10: =+C9+1 -> 7

Sheet Triangulo1
C2: Calcula el IBNR del siguiente triangulo usando Chain Ladder, BF y Cape Cod
D3: 1. el loss ratio a priori es 55%
D4: 2. tasa de interes | E4: 0.06
C7: Contesta las sig preguntas:
D8: 1. Qué metodología escogerías para cada trimestre y por qué?
D9: 2. Excluiste algun periodo para el calculo de lo factores? Di que periodo y en que desarrollo y por qué
D10: 3. Cómo sale el bakctesting para tu selección de ultimate para los trimestres del 1Q19 al 4Q20?
D11: 4. Qué duración tiene está cartera?
C13: TRIÁNGULO-PAGADO
D15: 1 | E15: =+D15+1 -> 2 | F15: =+E15+1 -> 3 | G15: =+F15+1 -> 4 | H15: =+G15+1 -> 5 | I15: =+H15+1 -> 6 | J15: =+I15+1 -> 7 | K15: =+J15+1 -> 8 | L15: =+K15+1 -> 9 | ... AA15: =+Z15+1 -> 24
C16: 1Q19 | D16: 6418198 | E16: 8351947 | F16: 9393090 | G16: 11183194 | H16: 12100800 | I16: 12721118 | J16: 13073728 | K16: 13548698 | L16: 13729852 | M16: 14178002 | N16: 14403018 | O16: 14589694 | P16: 14666170 | Q16: 14699145 | R16: 14709918 | S16: 14721902 | T16: 14723975 | U16: 14724778 | V16: 14725216 | W16: 14725343 | X16: 14725356 | Y16: 14725361 | Z16: 14725369 | AA16: 14725385
C17: 2Q19 | D17: 7475822 | E17: 10450029 | F17: 12515657 | G17: 13149304 | H17: 14417681 | I17: 15145227 | J17: 15971980 | K17: 16442175 | L17: 16761977 | M17: 17230340 | N17: 17479823 | O17: 17658472 | P17: 17691106 | Q17: 17707511 | R17: 17727251 | S17: 17731572 | T17: 17733454 | U17: 17734435 | V17: 17734974 | W17: 17735197 | X17: 17735258 | Y17: 17735268 | Z17: 17735279
C18: 3Q19 | D18: 4944676 | E18: 5651989 | F18: 6603749 | G18: 7627857 | H18: 8503366 | I18: 9687265 | J18: 10329156 | K18: 10705380 | L18: 11007279 | M18: 11432174 | N18: 11644639 | O18: 11802250 | P18: 11840837 | Q18: 11864201 | R18: 11873586 | S18: 11878223 | T18: 11880065 | U18: 11880905 | V18: 11881492 | W18: 11881607 | X18: 11881725 | Y18: 11881761
C19: 4Q19 | D19: 5990844 | E19: 12990844 | F19: 14795084 | G19: 15558421 | H19: 16698078 | I19: 17591115 | J19: 17858613 | K19: 18161498 | L19: 18751439 | M19: 18855100 | N19: 19152179 | O19: 19349458 | P19: 19426010 | Q19: 19444545 | R19: 19453256 | S19: 19457999 | T19: 19459976 | U19: 19461146 | V19: 19461559 | W19: 19461649 | X19: 19461650
C20: 1Q20 | D20: 6106533 | E20: 7227067 | F20: 8316481 | G20: 8778769 | H20: 9616196 | I20: 9944940 | J20: 10596973 | K20: 10938865 | L20: 11091033 | M20: 11574757 | N20: 11660948 | O20: 11754449 | P20: 11785976 | Q20: 11801623 | R20: 11808422 | S20: 11812430 | T20: 11814677 | U20: 11815553 | V20: 11815994 | W20: 11816173
C21: 2Q20 | D21: 3511339 | E21: 5097855 | F21: 6037374 | G21: 6436248 | H21: 7366573 | I21: 8575992 | J21: 9082448 | K21: 12082448 | L21: 12687409 | M21: 12838372 | N21: 12930641 | O21: 12990612 | P21: 13017211 | Q21: 13032985 | R21: 13041104 | S21: 13045224 | T21: 13046906 | U21: 13047997 | V21: 13048471
C22: 3Q20 | D22: 4141271 | E22: 5675304 | F22: 6514051 | G22: 7799341 | H22: 8118940 | I22: 8328067 | J22: 9073367 | K22: 9580777 | L22: 10084545 | M22: 10574369 | N22: 10704764 | O22: 10779530 | P22: 10810916 | Q22: 10825407 | R22: 10831969 | S22: 10836654 | T22: 10839043 | U22: 10840140
C23: 4Q20 | D23: 6591656 | E23: 9149839 | F23: 9876574 | G23: 11324778 | H23: 11791969 | I23: 12446387 | J23: 12820241 | K23: 13419392 | L23: 13586619 | M23: 13861205 | N23: 13987078 | O23: 14043493 | P23: 14079323 | Q23: 14095393 | R23: 14104571 | S23: 14109322 | T23: 14111136
C24: 1Q21 | D24: 6289704 | E24: 9074583 | F24: 11031640 | G24: 12328713 | H24: 12743016 | I24: 13716063 | J24: 13936735 | K24: 14684360 | L24: 15224487 | M24: 15505624 | N24: 15616491 | O24: 15669883 | P24: 15701026 | Q24: 15717007 | R24: 15725357 | S24: 15729334
C25: 2Q21 | D25: 4959185 | E25: 7332815 | F25: 8942057 | G25: 10413724 | H25: 11109326 | I25: 11743877 | J25: 12264947 | K25: 13331758 | L25: 13881470 | M25: 14105853 | N25: 14231236 | O25: 14285043 | P25: 14317196 | Q25: 14335249 | R25: 14343596
C26: 3Q21 | D26: 6194048 | E26: 7741218 | F26: 9386858 | G26: 9734366 | H26: 10964336 | I26: 11346897 | J26: 13064544 | K26: 14121948 | L26: 14605429 | M26: 14862271 | N26: 15012968 | O26: 15074585 | P26: 15104696 | Q26: 15119935
C27: 4Q21 | D27: 6500694 | E27: 9436157 | F27: 11552953 | G27: 12130358 | H27: 13369514 | I27: 15030308 | J27: 16697100 | K27: 17828453 | L27: 18294564 | M27: 18522862 | N27: 18641988 | O27: 18693587 | P27: 18730024
C28: 1Q22 | D28: 5205434 | E28: 7752400 | F28: 9411446 | G28: 10805763 | H28: 13284336 | I28: 15384835 | J28: 17438864 | K28: 18514044 | L28: 19125680 | M28: 19431036 | N28: 19572822 | O28: 19627354
C29: 2Q22 | D29: 5184519 | E29: 7275135 | F29: 7974797 | G29: 11597296 | H29: 14585912 | I29: 16285147 | J29: 18338971 | K29: 19214501 | L29: 19700684 | M29: 19926910 | N29: 20049671
C30: 3Q22 | D30: 3419011 | E30: 4773306 | F30: 8697825 | G30: 12220494 | H30: 14462971 | I30: 16656668 | J30: 19017438 | K30: 19939378 | L30: 20384099 | M30: 20688336
C31: 4Q22 | D31: 5498188 | E31: 10669557 | F31: 14420577 | G31: 17838126 | H31: 20243242 | I31: 22179116 | J31: 24155749 | K31: 25145296 | L31: 25647723
C32: 1Q23 | D32: 6382667 | E32: 10460689 | F32: 15242265 | G32: 19075882 | H32: 21908553 | I32: 23938666 | J32: 25653115 | K32: 26811464
C33: 2Q23 | D33: 3022770 | E33: 7899209 | F33: 11259161 | G33: 14497513 | H33: 17221120 | I33: 19234288 | J33: 21399003
C34: 3Q23 | D34: 6936281 | E34: 21936281 | F34: 25150070 | G34: 28898330 | H34: 31903741 | I34: 33589263
C35: 4Q23 | D35: 6691248 | E35: 11756013 | F35: 15391294 | G35: 18736499 | H35: 21705785
C36: 1Q24 | D36: 4191817 | E36: 9775450 | F36: 14374440 | G36: 17306094
C37: 2Q24 | D37: 5916671 | E37: 11716355 | F37: 15374462
C38: 3Q24 | D38: 4926500 | E38: 9321834
C39: 4Q24 | D39: 5149958
C41: FACTORES
D43: 1 | E43: =+D43+1 -> 2 | F43: =+E43+1 -> 3 | G43: =+F43+1 -> 4 | H43: =+G43+1 -> 5 | I43: =+H43+1 -> 6 | J43: =+I43+1 -> 7 | K43: =+J43+1 -> 8 | L43: =+K43+1 -> 9 | ... AA43: =+Z43+1 -> 24
C44: 1Q19 | D44: =E16/D16 -> 1.3012916 | E44: =F16/E16 -> 1.1246587 | F44: =G16/F16 -> 1.1905767 | G44: =H16/G16 -> 1.0820522 | H44: =I16/H16 -> 1.0512626 | I44: =J16/I16 -> 1.0277185 | J44: =K16/J16 -> 1.0363301 | K44: =L16/K16 -> 1.0133706 | ... Z44: =AA16/Z16 -> 1.0000011
C45: 2Q19 | D45: =E17/D17 -> 1.3978435 | E45: =F17/E17 -> 1.1976672 | F45: =G17/F17 -> 1.0506283 | G45: =H17/G17 -> 1.0964596 | H45: =I17/H17 -> 1.0504621 | I45: =J17/I17 -> 1.0545884 | J45: =K17/J17 -> 1.0294387 | K45: =L17/K17 -> 1.0194501 | ... Y45: =Z17/Y17 -> 1.0000006
C46: 3Q19 | D46: =E18/D18 -> 1.1430454 | E46: =F18/E18 -> 1.1683938 | F46: =G18/F18 -> 1.1550798 | G46: =H18/G18 -> 1.1147778 | H46: =I18/H18 -> 1.1392271 | I46: =J18/I18 -> 1.0662613 | J46: =K18/J18 -> 1.0364235 | K46: =L18/K18 -> 1.0282007 | ... X46: =Y18/X18 -> 1.000003
C47: 4Q19 | D47: =E19/D19 -> 2.1684497 | E47: =F19/E19 -> 1.1388855 | F47: =G19/F19 -> 1.051594 | G47: =H19/G19 -> 1.0732502 | H47: =I19/H19 -> 1.0534814 | I47: =J19/I19 -> 1.0152064 | J47: =K19/J19 -> 1.0169602 | K47: =L19/K19 -> 1.0324831 | ... W47: =X19/W19 -> 1.0000001
...

Sheet 1_CL
A1: CHAIN-LADDER — Triángulo Proyectado e IBNR | Vinculado a hojas 1_Triangulo y 2_Factores
A2: AZUL=observado (hoja 1) · AMARILLO=proyección CL = C_{i,j-1} × f̂_{j-1} (hoja 2) · VERDE=IBNR
A3: AO | B3: Trim. | C3: T01 | D3: T02 | E3: T03 | F3: T04 | G3: T05 | H3: T06 | I3: T07 | J3: T08 | K3: T09 | L3: T10 | M3: T11 | N3: T12 | O3: T13 | P3: T14 | Q3: T15 | R3: T16 | S3: T17 | T3: T18 | U3: T19 | V3: T20 | W3: T21 | X3: T22 | Y3: T23 | Z3: T24 | AA3: Último Proy. | AB3: Pagado Actual | AC3: IBNR CL
A4: AO01 | B4: 1Q19 | R4: =IF(Triangulo1!S16=0,"-",Triangulo1!S16) -> 14721902 | S4: =IF(Triangulo1!T16=0,"-",Triangulo1!T16) -> 14723975 | T4: =IF(Triangulo1!U16=0,"-",Triangulo1!U16) -> 14724778 | U4: =IF(Triangulo1!V16=0,"-",Triangulo1!V16) -> 14725216 | V4: =IF(Triangulo1!W16=0,"-",Triangulo1!W16) -> 14725343 | W4: =IF(Triangulo1!X16=0,"-",Triangulo1!X16) -> 14725356 | X4: =IF(Triangulo1!Y16=0,"-",Triangulo1!Y16) -> 14725361 | Y4: =IF(Triangulo1!Z16=0,"-",Triangulo1!Z16) -> 14725369 | Z4: =IF(Triangulo1!AA16=0,"-",Triangulo1!AA16) -> 14725385 | AA4: =+Z4 -> 14725385 | AB4: =+Z4 -> 14725385 | AC4: =AA4-AB4 -> 0
A5: AO02 | B5: 2Q19 | Q5: =IF(Triangulo1!R17=0,"-",Triangulo1!R17) -> 17727251 | R5: =IF(Triangulo1!S17=0,"-",Triangulo1!S17) -> 17731572 | S5: =IF(Triangulo1!T17=0,"-",Triangulo1!T17) -> 17733454 | T5: =IF(Triangulo1!U17=0,"-",Triangulo1!U17) -> 17734435 | U5: =IF(Triangulo1!V17=0,"-",Triangulo1!V17) -> 17734974 | V5: =IF(Triangulo1!W17=0,"-",Triangulo1!W17) -> 17735197 | W5: =IF(Triangulo1!X17=0,"-",Triangulo1!X17) -> 17735258 | X5: =IF(Triangulo1!Y17=0,"-",Triangulo1!Y17) -> 17735268 | Y5: =IF(Triangulo1!Z17=0,"-",Triangulo1!Z17) -> 17735279 | Z5: =+Y5*Y$30 -> 17735298 | AA5: =+Z5 -> 17735298 | AB5: =+Y5 -> 17735279 | AC5: =AA5-AB5 -> 19.270448
A6: AO03 | B6: 3Q19 | P6: =IF(Triangulo1!Q18=0,"-",Triangulo1!Q18) -> 11864201 | Q6: =IF(Triangulo1!R18=0,"-",Triangulo1!R18) -> 11873586 | R6: =IF(Triangulo1!S18=0,"-",Triangulo1!S18) -> 11878223 | S6: =IF(Triangulo1!T18=0,"-",Triangulo1!T18) -> 11880065 | T6: =IF(Triangulo1!U18=0,"-",Triangulo1!U18) -> 11880905 | U6: =IF(Triangulo1!V18=0,"-",Triangulo1!V18) -> 11881492 | V6: =IF(Triangulo1!W18=0,"-",Triangulo1!W18) -> 11881607 | W6: =IF(Triangulo1!X18=0,"-",Triangulo1!X18) -> 11881725 | X6: =IF(Triangulo1!Y18=0,"-",Triangulo1!Y18) -> 11881761 | Y6: =+X6*X$30 -> 11881768 | Z6: =+Y6*Y$30 -> 11881781 | AA6: =+Z6 -> 11881781 | AB6: =+X6 -> 11881761 | AC6: =AA6-AB6 -> 19.864942
A7: AO04 | B7: 4Q19 | O7: =IF(Triangulo1!P19=0,"-",Triangulo1!P19) -> 19426010 | P7: =IF(Triangulo1!Q19=0,"-",Triangulo1!Q19) -> 19444545 | Q7: =IF(Triangulo1!R19=0,"-",Triangulo1!R19) -> 19453256 | R7: =IF(Triangulo1!S19=0,"-",Triangulo1!S19) -> 19457999 | S7: =IF(Triangulo1!T19=0,"-",Triangulo1!T19) -> 19459976 | T7: =IF(Triangulo1!U19=0,"-",Triangulo1!U19) -> 19461146 | U7: =IF(Triangulo1!V19=0,"-",Triangulo1!V19) -> 19461559 | V7: =IF(Triangulo1!W19=0,"-",Triangulo1!W19) -> 19461649 | W7: =IF(Triangulo1!X19=0,"-",Triangulo1!X19) -> 19461650 | X7: =+W7*W$30 -> 19461672 | Y7: =+X7*X$30 -> 19461684 | Z7: =+Y7*Y$30 -> 19461705 | AA7: =+Z7 -> 19461705 | AB7: =+W7 -> 19461650 | AC7: =AA7-AB7 -> 54.921351
A8: AO05 | B8: 1Q20 | N8: =IF(Triangulo1!O20=0,"-",Triangulo1!O20) -> 11754449 | O8: =IF(Triangulo1!P20=0,"-",Triangulo1!P20) -> 11785976 | P8: =IF(Triangulo1!Q20=0,"-",Triangulo1!Q20) -> 11801623 | Q8: =IF(Triangulo1!R20=0,"-",Triangulo1!R20) -> 11808422 | R8: =IF(Triangulo1!S20=0,"-",Triangulo1!S20) -> 11812430 | S8: =IF(Triangulo1!T20=0,"-",Triangulo1!T20) -> 11814677 | T8: =IF(Triangulo1!U20=0,"-",Triangulo1!U20) -> 11815553 | U8: =IF(Triangulo1!V20=0,"-",Triangulo1!V20) -> 11815994 | V8: =IF(Triangulo1!W20=0,"-",Triangulo1!W20) -> 11816173 | W8: =+V8*V$30 -> 11816209 | X8: =+W8*W$30 -> 11816222 | Y8: =+X8*X$30 -> 11816229 | Z8: =+Y8*Y$30 -> 11816242 | AA8: =+Z8 -> 11816242 | AB8: =+V8 -> 11816173 | AC8: =AA8-AB8 -> 69.088413
A9: AO06 | B9: 2Q20 | M9: =IF(Triangulo1!N21=0,"-",Triangulo1!N21) -> 12930641 | N9: =IF(Triangulo1!O21=0,"-",Triangulo1!O21) -> 12990612 | O9: =IF(Triangulo1!P21=0,"-",Triangulo1!P21) -> 13017211 | P9: =IF(Triangulo1!Q21=0,"-",Triangulo1!Q21) -> 13032985 | Q9: =IF(Triangulo1!R21=0,"-",Triangulo1!R21) -> 13041104 | R9: =IF(Triangulo1!S21=0,"-",Triangulo1!S21) -> 13045224 | S9: =IF(Triangulo1!T21=0,"-",Triangulo1!T21) -> 13046906 | T9: =IF(Triangulo1!U21=0,"-",Triangulo1!U21) -> 13047997 | U9: =IF(Triangulo1!V21=0,"-",Triangulo1!V21) -> 13048471 | V9: =+U9*U$30 -> 13048598 | W9: =+V9*V$30 -> 13048637 | X9: =+W9*W$30 -> 13048652 | Y9: =+X9*X$30 -> 13048660 | Z9: =+Y9*Y$30 -> 13048674 | AA9: =+Z9 -> 13048674 | AB9: =+U9 -> 13048471 | AC9: =AA9-AB9 -> 202.94963
A10: AO07 | B10: 3Q20 | L10: =IF(Triangulo1!M22=0,"-",Triangulo1!M22) -> 10574369 | M10: =IF(Triangulo1!N22=0,"-",Triangulo1!N22) -> 10704764 | N10: =IF(Triangulo1!O22=0,"-",Triangulo1!O22) -> 10779530 | O10: =IF(Triangulo1!P22=0,"-",Triangulo1!P22) -> 10810916 | P10: =IF(Triangulo1!Q22=0,"-",Triangulo1!Q22) -> 10825407 | Q10: =IF(Triangulo1!R22=0,"-",Triangulo1!R22) -> 10831969 | R10: =IF(Triangulo1!S22=0,"-",Triangulo1!S22) -> 10836654 | S10: =IF(Triangulo1!T22=0,"-",Triangulo1!T22) -> 10839043 | T10: =IF(Triangulo1!U22=0,"-",Triangulo1!U22) -> 10840140 | U10: =+T10*T$30 -> 10840494 | V10: =+U10*U$30 -> 10840599 | W10: =+V10*V$30 -> 10840632 | X10: =+W10*W$30 -> 10840644 | Y10: =+X10*X$30 -> 10840650 | Z10: =+Y10*Y$30 -> 10840662 | AA10: =+Z10 -> 10840662 | AB10: =+T10 -> 10840140 | AC10: =AA10-AB10 -> 522.18308
A11: AO08 | B11: 4Q20 | K11: =IF(Triangulo1!L23=0,"-",Triangulo1!L23) -> 13586619 | L11: =IF(Triangulo1!M23=0,"-",Triangulo1!M23) -> 13861205 | M11: =IF(Triangulo1!N23=0,"-",Triangulo1!N23) -> 13987078 | N11: =IF(Triangulo1!O23=0,"-",Triangulo1!O23) -> 14043493 | O11: =IF(Triangulo1!P23=0,"-",Triangulo1!P23) -> 14079323 | P11: =IF(Triangulo1!Q23=0,"-",Triangulo1!Q23) -> 14095393 | Q11: =IF(Triangulo1!R23=0,"-",Triangulo1!R23) -> 14104571 | R11: =IF(Triangulo1!S23=0,"-",Triangulo1!S23) -> 14109322 | S11: =IF(Triangulo1!T23=0,"-",Triangulo1!T23) -> 14111136 | T11: =+S11*S$30 -> 14112109 | U11: =+T11*T$30 -> 14112569 | V11: =+U11*U$30 -> 14112706 | W11: =+V11*V$30 -> 14112749 | X11: =+W11*W$30 -> 14112765 | Y11: =+X11*X$30 -> 14112773 | Z11: =+Y11*Y$30 -> 14112788 | AA11: =+Z11 -> 14112788 | AB11: =+S11 -> 14111136 | AC11: =AA11-AB11 -> 1652.4212
A12: AO09 | B12: 1Q21 | J12: =IF(Triangulo1!K24=0,"-",Triangulo1!K24) -> 14684360 | K12: =IF(Triangulo1!L24=0,"-",Triangulo1!L24) -> 15224487 | L12: =IF(Triangulo1!M24=0,"-",Triangulo1!M24) -> 15505624 | M12: =IF(Triangulo1!N24=0,"-",Triangulo1!N24) -> 15616491 | N12: =IF(Triangulo1!O24=0,"-",Triangulo1!O24) -> 15669883 | O12: =IF(Triangulo1!P24=0,"-",Triangulo1!P24) -> 15701026 | P12: =IF(Triangulo1!Q24=0,"-",Triangulo1!Q24) -> 15717007 | Q12: =IF(Triangulo1!R24=0,"-",Triangulo1!R24) -> 15725357 | R12: =IF(Triangulo1!S24=0,"-",Triangulo1!S24) -> 15729334 | S12: =+R12*R30 -> 15731537 | T12: =+S12*S30 -> 15732621 | U12: =+T12*T30 -> 15733134 | V12: =+U12*U30 -> 15733287 | W12: =+V12*V30 -> 15733334 | X12: =+W12*W30 -> 15733352 | Y12: =+X12*X30 -> 15733362 | Z12: =+Y12*Y30 -> 15733379 | AA12: =+Z12 -> 15733379 | AB12: =+R12 -> 15729334 | AC12: =AA12-AB12 -> 4044.684
A13: AO10 | B13: 2Q21 | I13: =IF(Triangulo1!J25=0,"-",Triangulo1!J25) -> 12264947 | J13: =IF(Triangulo1!K25=0,"-",Triangulo1!K25) -> 13331758 | K13: =IF(Triangulo1!L25=0,"-",Triangulo1!L25) -> 13881470 | L13: =IF(Triangulo1!M25=0,"-",Triangulo1!M25) -> 14105853 | M13: =IF(Triangulo1!N25=0,"-",Triangulo1!N25) -> 14231236 | N13: =IF(Triangulo1!O25=0,"-",Triangulo1!O25) -> 14285043 | O13: =IF(Triangulo1!P25=0,"-",Triangulo1!P25) -> 14317196 | P13: =IF(Triangulo1!Q25=0,"-",Triangulo1!Q25) -> 14335249 | Q13: =IF(Triangulo1!R25=0,"-",Triangulo1!R25) -> 14343596 | R13: =+Q13*Q30 -> 14348008 | S13: =+R13*R30 -> 14350017 | T13: =+S13*S30 -> 14351006 | U13: =+T13*T30 -> 14351475 | V13: =+U13*U30 -> 14351614 | W13: =+V13*V30 -> 14351657 | X13: =+W13*W30 -> 14351674 | Y13: =+X13*X30 -> 14351682 | Z13: =+Y13*Y30 -> 14351698 | AA13: =+Z13 -> 14351698 | AB13: =+Q13 -> 14343596 | AC13: =AA13-AB13 -> 8101.7825
A14: AO11 | B14: 3Q21 | H14: =IF(Triangulo1!I26=0,"-",Triangulo1!I26) -> 11346897 | I14: =IF(Triangulo1!J26=0,"-",Triangulo1!J26) -> 13064544 | J14: =IF(Triangulo1!K26=0,"-",Triangulo1!K26) -> 14121948 | K14: =IF(Triangulo1!L26=0,"-",Triangulo1!L26) -> 14605429 | L14: =IF(Triangulo1!M26=0,"-",Triangulo1!M26) -> 14862271 | M14: =IF(Triangulo1!N26=0,"-",Triangulo1!N26) -> 15012968 | N14: =IF(Triangulo1!O26=0,"-",Triangulo1!O26) -> 15074585 | O14: =IF(Triangulo1!P26=0,"-",Triangulo1!P26) -> 15104696 | P14: =IF(Triangulo1!Q26=0,"-",Triangulo1!Q26) -> 15119935 | Q14: =+P14*P30 -> 15128841 | R14: =+Q14*Q30 -> 15133495 | S14: =+R14*R30 -> 15135614 | T14: =+S14*S30 -> 15136657 | U14: =+T14*T30 -> 15137151 | V14: =+U14*U30 -> 15137298 | W14: =+V14*V30 -> 15137344 | X14: =+W14*W30 -> 15137361 | ... Z14: =+Y14*Y30 -> 15137386 | AA14: =+Z14 -> 15137386 | AB14: =+P14 -> 15119935 | AC14: =AA14-AB14 -> 17451.426
A15: AO12 | B15: 4Q21 | G15: =IF(Triangulo1!H27=0,"-",Triangulo1!H27) -> 13369514 | H15: =IF(Triangulo1!I27=0,"-",Triangulo1!I27) -> 15030308 | I15: =IF(Triangulo1!J27=0,"-",Triangulo1!J27) -> 16697100 | J15: =IF(Triangulo1!K27=0,"-",Triangulo1!K27) -> 17828453 | K15: =IF(Triangulo1!L27=0,"-",Triangulo1!L27) -> 18294564 | L15: =IF(Triangulo1!M27=0,"-",Triangulo1!M27) -> 18522862 | M15: =IF(Triangulo1!N27=0,"-",Triangulo1!N27) -> 18641988 | N15: =IF(Triangulo1!O27=0,"-",Triangulo1!O27) -> 18693587 | O15: =IF(Triangulo1!P27=0,"-",Triangulo1!P27) -> 18730024 | P15: =+O15*O30 -> 18751303 | Q15: =+P15*P30 -> 18762348 | R15: =+Q15*Q30 -> 18768120 | S15: =+R15*R30 -> 18770748 | T15: =+S15*S30 -> 18772042 | U15: =+T15*T30 -> 18772654 | V15: =+U15*U30 -> 18772836 | W15: =+V15*V30 -> 18772893 | ... Z15: =+Y15*Y30 -> 18772946 | AA15: =+Z15 -> 18772946 | AB15: =+O15 -> 18730024 | AC15: =AA15-AB15 -> 42921.81
A16: AO13 | B16: 1Q22 | F16: =IF(Triangulo1!G28=0,"-",Triangulo1!G28) -> 10805763 | G16: =IF(Triangulo1!H28=0,"-",Triangulo1!H28) -> 13284336 | H16: =IF(Triangulo1!I28=0,"-",Triangulo1!I28) -> 15384835 | I16: =IF(Triangulo1!J28=0,"-",Triangulo1!J28) -> 17438864 | J16: =IF(Triangulo1!K28=0,"-",Triangulo1!K28) -> 18514044 | K16: =IF(Triangulo1!L28=0,"-",Triangulo1!L28) -> 19125680 | L16: =IF(Triangulo1!M28=0,"-",Triangulo1!M28) -> 19431036 | M16: =IF(Triangulo1!N28=0,"-",Triangulo1!N28) -> 19572822 | N16: =IF(Triangulo1!O28=0,"-",Triangulo1!O28) -> 19627354 | O16: =+N16*N30 -> 19671564 | P16: =+O16*O30 -> 19693913 | Q16: =+P16*P30 -> 19705513 | R16: =+Q16*Q30 -> 19711575 | S16: =+R16*R30 -> 19714335 | T16: =+S16*S30 -> 19715694 | U16: =+T16*T30 -> 19716337 | V16: =+U16*U30 -> 19716528 | ... Z16: =+Y16*Y30 -> 19716644 | AA16: =+Z16 -> 19716644 | AB16: =+N16 -> 19627354 | AC16: =AA16-AB16 -> 89289.649
A17: AO14 | B17: 2Q22 | E17: =IF(Triangulo1!F29=0,"-",Triangulo1!F29) -> 7974797 | F17: =IF(Triangulo1!G29=0,"-",Triangulo1!G29) -> 11597296 | G17: =IF(Triangulo1!H29=0,"-",Triangulo1!H29) -> 14585912 | H17: =IF(Triangulo1!I29=0,"-",Triangulo1!I29) -> 16285147 | I17: =IF(Triangulo1!J29=0,"-",Triangulo1!J29) -> 18338971 | J17: =IF(Triangulo1!K29=0,"-",Triangulo1!K29) -> 19214501 | K17: =IF(Triangulo1!L29=0,"-",Triangulo1!L29) -> 19700684 | L17: =IF(Triangulo1!M29=0,"-",Triangulo1!M29) -> 19926910 | M17: =IF(Triangulo1!N29=0,"-",Triangulo1!N29) -> 20049671 | N17: =+M17*M30 -> 20127097 | O17: =+N17*N30 -> 20172433 | P17: =+O17*O30 -> 20195350 | Q17: =+P17*P30 -> 20207246 | R17: =+Q17*Q30 -> 20213462 | S17: =+R17*R30 -> 20216293 | T17: =+S17*S30 -> 20217686 | U17: =+T17*T30 -> 20218345 | ... Z17: =+Y17*Y30 -> 20218660 | AA17: =+Z17 -> 20218660 | AB17: =+M17 -> 20049671 | AC17: =AA17-AB17 -> 168988.85
A18: AO15 | B18: 3Q22 | D18: =IF(Triangulo1!E30=0,"-",Triangulo1!E30) -> 4773306 | E18: =IF(Triangulo1!F30=0,"-",Triangulo1!F30) -> 8697825 | F18: =IF(Triangulo1!G30=0,"-",Triangulo1!G30) -> 12220494 | G18: =IF(Triangulo1!H30=0,"-",Triangulo1!H30) -> 14462971 | H18: =IF(Triangulo1!I30=0,"-",Triangulo1!I30) -> 16656668 | I18: =IF(Triangulo1!J30=0,"-",Triangulo1!J30) -> 19017438 | J18: =IF(Triangulo1!K30=0,"-",Triangulo1!K30) -> 19939378 | K18: =IF(Triangulo1!L30=0,"-",Triangulo1!L30) -> 20384099 | L18: =IF(Triangulo1!M30=0,"-",Triangulo1!M30) -> 20688336 | M18: =+L18*L30 -> 20855893 | N18: =+M18*M30 -> 20936432 | O18: =+N18*N30 -> 20983591 | P18: =+O18*O30 -> 21007431 | Q18: =+P18*P30 -> 21019805 | R18: =+Q18*Q30 -> 21026271 | S18: =+R18*R30 -> 21029215 | T18: =+S18*S30 -> 21030664 | ... Z18: =+Y18*Y30 -> 21031677 | AA18: =+Z18 -> 21031677 | AB18: =+L18 -> 20688336 | AC18: =AA18-AB18 -> 343341.34
A19: AO16 | B19: 4Q22 | C19: =IF(Triangulo1!D31=0,"-",Triangulo1!D31) -> 5498188 | D19: =IF(Triangulo1!E31=0,"-",Triangulo1!E31) -> 10669557 | E19: =IF(Triangulo1!F31=0,"-",Triangulo1!F31) -> 14420577 | F19: =IF(Triangulo1!G31=0,"-",Triangulo1!G31) -> 17838126 | G19: =IF(Triangulo1!H31=0,"-",Triangulo1!H31) -> 20243242 | H19: =IF(Triangulo1!I31=0,"-",Triangulo1!I31) -> 22179116 | I19: =IF(Triangulo1!J31=0,"-",Triangulo1!J31) -> 24155749 | J19: =IF(Triangulo1!K31=0,"-",Triangulo1!K31) -> 25145296 | K19: =IF(Triangulo1!L31=0,"-",Triangulo1!L31) -> 25647723 | L19: =+K19*K30 -> 26047473 | M19: =+L19*L30 -> 26258435 | N19: =+M19*M30 -> 26359837 | O19: =+N19*N30 -> 26419212 | P19: =+O19*O30 -> 26449226 | Q19: =+P19*P30 -> 26464806 | R19: =+Q19*Q30 -> 26472947 | S19: =+R19*R30 -> 26476654 | ... Z19: =+Y19*Y30 -> 26479754 | AA19: =+Z19 -> 26479754 | AB19: =+K19 -> 25647723 | AC19: =AA19-AB19 -> 832031.14
A20: AO17 | B20: 1Q23 | C20: =IF(Triangulo1!D32=0,"-",Triangulo1!D32) -> 6382667 | D20: =IF(Triangulo1!E32=0,"-",Triangulo1!E32) -> 10460689 | E20: =IF(Triangulo1!F32=0,"-",Triangulo1!F32) -> 15242265 | F20: =IF(Triangulo1!G32=0,"-",Triangulo1!G32) -> 19075882 | G20: =IF(Triangulo1!H32=0,"-",Triangulo1!H32) -> 21908553 | H20: =IF(Triangulo1!I32=0,"-",Triangulo1!I32) -> 23938666 | I20: =IF(Triangulo1!J32=0,"-",Triangulo1!J32) -> 25653115 | J20: =IF(Triangulo1!K32=0,"-",Triangulo1!K32) -> 26811464 | K20: =+J20*J30 -> 27578440 | L20: =+K20*K30 -> 28008283 | M20: =+L20*L30 -> 28235125 | N20: =+M20*M30 -> 28344161 | O20: =+N20*N30 -> 28408006 | P20: =+O20*O30 -> 28440280 | Q20: =+P20*P30 -> 28457032 | R20: =+Q20*Q30 -> 28465786 | ... Z20: =+Y20*Y30 -> 28473105 | AA20: =+Z20 -> 28473105 | AB20: =+J20 -> 26811464 | AC20: =AA20-AB20 -> 1661641.4
A21: AO18 | B21: 2Q23 | C21: =IF(Triangulo1!D33=0,"-",Triangulo1!D33) -> 3022770 | D21: =IF(Triangulo1!E33=0,"-",Triangulo1!E33) -> 7899209 | E21: =IF(Triangulo1!F33=0,"-",Triangulo1!F33) -> 11259161 | F21: =IF(Triangulo1!G33=0,"-",Triangulo1!G33) -> 14497513 | G21: =IF(Triangulo1!H33=0,"-",Triangulo1!H33) -> 17221120 | H21: =IF(Triangulo1!I33=0,"-",Triangulo1!I33) -> 19234288 | I21: =IF(Triangulo1!J33=0,"-",Triangulo1!J33) -> 21399003 | J21: =+I21*I30 -> 22606803 | K21: =+J21*J30 -> 23253500 | L21: =+K21*K30 -> 23615933 | M21: =+L21*L30 -> 23807201 | N21: =+M21*M30 -> 23899137 | O21: =+N21*N30 -> 23952970 | P21: =+O21*O30 -> 23980182 | Q21: =+P21*P30 -> 23994308 | ... Z21: =+Y21*Y30 -> 24007860 | AA21: =+Z21 -> 24007860 | AB21: =+I21 -> 21399003 | AC21: =AA21-AB21 -> 2608857.4
A22: AO19 | B22: 3Q23 | C22: =IF(Triangulo1!D34=0,"-",Triangulo1!D34) -> 6936281 | D22: =IF(Triangulo1!E34=0,"-",Triangulo1!E34) -> 21936281 | E22: =IF(Triangulo1!F34=0,"-",Triangulo1!F34) -> 25150070 | F22: =IF(Triangulo1!G34=0,"-",Triangulo1!G34) -> 28898330 | G22: =IF(Triangulo1!H34=0,"-",Triangulo1!H34) -> 31903741 | H22: =IF(Triangulo1!I34=0,"-",Triangulo1!I34) -> 33589263 | I22: =H30*H22 -> 37356679 | J22: =I30*I22 -> 39465161 | K22: =J30*J22 -> 40594112 | L22: =K30*K22 -> 41226820 | M22: =L30*L22 -> 41560721 | N22: =M30*M22 -> 41721215 | O22: =N30*N22 -> 41815192 | P22: =O30*O22 -> 41862698 | ... Z22: =Y30*Y22 -> 41911015 | AA22: =+Z22 -> 41911015 | AB22: =+H22 -> 33589263 | AC22: =AA22-AB22 -> 8321752.4
A23: AO20 | B23: 4Q23 | C23: =IF(Triangulo1!D35=0,"-",Triangulo1!D35) -> 6691248 | D23: =IF(Triangulo1!E35=0,"-",Triangulo1!E35) -> 11756013 | E23: =IF(Triangulo1!F35=0,"-",Triangulo1!F35) -> 15391294 | F23: =IF(Triangulo1!G35=0,"-",Triangulo1!G35) -> 18736499 | G23: =IF(Triangulo1!H35=0,"-",Triangulo1!H35) -> 21705785 | H23: =G30*G23 -> 23968067 | I23: =H30*H23 -> 26656357 | J23: =I30*I23 -> 28160892 | K23: =J30*J23 -> 28966470 | L23: =K30*K23 -> 29417947 | M23: =L30*L23 -> 29656207 | N23: =M30*M23 -> 29770730 | O23: =N30*N23 -> 29837788 | ... Z23: =Y30*Y23 -> 29906164 | AA23: =+Z23 -> 29906164 | AB23: =+G23 -> 21705785 | AC23: =AA23-AB23 -> 8200379.3
A24: AO21 | B24: 1Q24 | C24: =IF(Triangulo1!D36=0,"-",Triangulo1!D36) -> 4191817 | D24: =IF(Triangulo1!E36=0,"-",Triangulo1!E36) -> 9775450 | E24: =IF(Triangulo1!F36=0,"-",Triangulo1!F36) -> 14374440 | F24: =IF(Triangulo1!G36=0,"-",Triangulo1!G36) -> 17306094 | G24: =F30*F24 -> 20108546 | H24: =G30*G24 -> 22204356 | I24: =H30*H24 -> 24694826 | J24: =I30*I24 -> 26088649 | K24: =J30*J24 -> 26834948 | L24: =K30*K24 -> 27253202 | M24: =L30*L24 -> 27473929 | N24: =M30*M24 -> 27580025 | ... Z24: =Y30*Y24 -> 27705493 | AA24: =+Z24 -> 27705493 | AB24: =+F24 -> 17306094 | AC24: =AA24-AB24 -> 10399399
A25: AO22 | B25: 2Q24 | C25: =IF(Triangulo1!D37=0,"-",Triangulo1!D37) -> 5916671 | D25: =IF(Triangulo1!E37=0,"-",Triangulo1!E37) -> 11716355 | E25: =IF(Triangulo1!F37=0,"-",Triangulo1!F37) -> 15374462 | F25: =E25*E30 -> 19154153 | G25: =F25*F30 -> 22255869 | H25: =G25*G30 -> 24575483 | I25: =H25*H30 -> 27331902 | J25: =I25*I30 -> 28874566 | K25: =J25*J30 -> 29700560 | L25: =K25*K30 -> 30163479 | M25: =L25*L30 -> 30407776 | ... Z25: =Y25*Y30 -> 30664068 | AA25: =+Z25 -> 30664068 | AB25: =+E25 -> 15374462 | AC25: =AA25-AB25 -> 15289606
A26: AO23 | B26: 3Q24 | C26: =IF(Triangulo1!D38=0,"-",Triangulo1!D38) -> 4926500 | D26: =IF(Triangulo1!E38=0,"-",Triangulo1!E38) -> 9321834 | E26: =D26*D30 -> 12561203 | F26: =E26*E30 -> 15649276 | G26: =F26*F30 -> 18183432 | H26: =G26*G30 -> 20078597 | I26: =H26*H30 -> 22330639 | J26: =I26*I30 -> 23591023 | K26: =J26*J30 -> 24265874 | L26: =K26*K30 -> 24644087 | ... Z26: =Y26*Y30 -> 25053077 | AA26: =+Z26 -> 25053077 | AB26: =+D26 -> 9321834 | AC26: =AA26-AB26 -> 15731243
A27: AO24 | B27: 4Q24 | C27: =IF(Triangulo1!D39=0,"-",Triangulo1!D39) -> 5149958 | D27: =C27*C30 -> 11056828 | E27: =D27*D30 -> 14899112 | F27: =E27*E30 -> 18561942 | G27: =F27*F30 -> 21567759 | H27: =G27*G30 -> 23815655 | I27: =H27*H30 -> 26486851 | J27: =I27*I30 -> 27981819 | K27: =J27*J30 -> 28782275 | ... Z27: =Y27*Y30 -> 29715993 | AA27: =+Z27 -> 29715993 | AB27: =+C27 -> 5149958 | AC27: =AA27-AB27 -> 24566035
A28: Numerado | C28: =SUM(D19:D26) -> 93535388 | D28: =SUM(E18:E25) -> 119910094 | E28: =SUM(F17:F24) -> 140170234 | F28: =SUM(G16:G23) -> 155315660 | G28: =SUM(H15:H22) -> 162298291 | H28: =SUM(I14:I21) -> 155764784 | I28: =SUM(J13:J20) -> 154906842 | J28: =SUM(K12:K19) -> 146864136 | K28: =SUM(L11:L18) -> 136904097 | L28: =SUM(M10:M17) -> 127817018 | M28: =SUM(N9:N16) -> 121164087 | N28: =SUM(O8:O15) -> 113546368 | O28: =SUM(P7:P14) -> 114372144 | P28: =SUM(Q6:Q13) -> 111181861 | Q28: =SUM(R5:R12) -> 114600758 | R28: =SUM(S4:S11) -> 113609232 | S28: =SUM(T4:T10) -> 99504954 | T28: =SUM(U4:U9) -> 88667706 | U28: =SUM(V4:V8) -> 75619969 | V28: =SUM(W4:W7) -> 63803989 | W28: =SUM(X4:X6) -> 44342390 | X28: =SUM(Y4:Y5) -> 32460648 | Y28: =SUM(Z4) -> 14725385
A29: Denominador | C29: =SUM(C19:C26) -> 43566142 | D29: =SUM(D18:D25) -> 88986860 | E29: =SUM(E17:E24) -> 112510429 | F29: =SUM(F16:F23) -> 133669903 | G29: =SUM(G15:G22) -> 146979389 | H29: =SUM(H14:H21) -> 140055925 | I29: =SUM(I13:I20) -> 146630728 | J29: =SUM(J12:J19) -> 142779738 | K29: =SUM(K11:K18) -> 134803032 | L29: =SUM(L10:L17) -> 126790130 | M29: =SUM(M9:M16) -> 120697988 | N29: =SUM(N8:N15) -> 113291182 | O29: =SUM(O7:O14) -> 114242354 | P29: =SUM(P6:P13) -> 111116410 | Q29: =SUM(Q5:Q12) -> 114565516 | R29: =SUM(R4:R11) -> 113593326 | S29: =SUM(S4:S10) -> 99498096 | T29: =SUM(T4:T9) -> 88664814 | U29: =SUM(U4:U8) -> 75619235 | V29: =SUM(V4:V7) -> 63803796 | W29: =SUM(W4:W6) -> 44342339 | X29: =SUM(X4:X5) -> 32460629 | Y29: =SUM(Y4) -> 14725369
A30: Factores | C30: =C28/C29 -> 2.1469743 | D30: =D28/D29 -> 1.3475034 | E30: =E28/E29 -> 1.2458421 | F30: =F28/F29 -> 1.1619344 | G30: =G28/G29 -> 1.1042248 | H30: =H28/H29 -> 1.1121613 | I30: =I28/I29 -> 1.0564419 | J30: =J28/J29 -> 1.0286063 | ... Y30: =Y28/Y29 -> 1.0000011 | Z30: 1
A31: Factor acum. F_j^{→25} | C31: =+C30*D31 -> 5.7701428 | D31: =+D30*E31 -> 2.6875695 | E31: =+E30*F31 -> 1.9944807 | F31: =+F30*G31 -> 1.6009097 | G31: =+G30*H31 -> 1.3777969 | H31: =+H30*I31 -> 1.2477504 | I31: =+I30*J31 -> 1.1219149 | J31: =+J30*K31 -> 1.061975 | ... Y31: =+Y30*Z31 -> 1.0000011 | Z31: 1
A32: % Desarrollado = 1/F_j | C32: =1/C31 -> 0.17330594 | D32: =1/D31 -> 0.3720834 | E32: =1/E31 -> 0.50138363 | F32: =1/F31 -> 0.62464486 | G32: =1/G31 -> 0.72579635 | H32: =1/H31 -> 0.80144236 | I32: =1/I31 -> 0.8913332 | J32: =1/J31 -> 0.94164172 | ... Y32: =1/Y31 -> 0.99999891 | Z32: 1
A33: Total | AA33: =+SUM(AA4:AA27) -> 5.0250146e+08 | AB33: =+SUM(AB4:AB27) -> 414213831 | AC33: =SUM(AC4:AC28) -> 88287626

Sheet 1_BF
A4: ELR a priori (BF): | B4: 0.55
A7: AO | B7: Trim. | C7: Pagado actual (diagonal) | D7: Prima Devengada | E7: % Des. (de 2_Factores) | F7: % No-Des. =1−%Des | G7: Apriori =Prima×ELR | H7: IBNR_BF =Apriori×%NoDes | I7: Último_BF =Pag+IBNR
A8: AO001 | B8: 1Q19 | C8: =+Triangulo1!E79 -> 14725385 | D8: =+Triangulo1!D79 -> 30470484 | E8: 1 | F8: =1-E8 -> 0 | G8: =+$B$4*D8 -> 16758766 | H8: =+G8*F8 -> 0 | I8: =+H8+C8 -> 14725385
A9: AO002 | B9: 2Q19 | C9: =+Triangulo1!E80 -> 17735279 | D9: =+Triangulo1!D80 -> 35502400 | E9: =+'1_CL'!Y32 -> 0.99999891 | F9: =1-E9 -> 1.086559e-06 | G9: =+$B$4*D9 -> 19526320 | H9: =+G9*F9 -> 21.216499 | I9: =+H9+C9 -> 17735300
A10: AO003 | B10: 3Q19 | C10: =+Triangulo1!E81 -> 11881761 | D10: =+Triangulo1!D81 -> 15118899 | E10: =+'1_CL'!X32 -> 0.99999833 | F10: =1-E10 -> 1.6718825e-06 | G10: =+$B$4*D10 -> 8315394.3 | H10: =+G10*F10 -> 13.902362 | I10: =+H10+C10 -> 11881775
A11: AO004 | B11: 4Q19 | C11: =+Triangulo1!E82 -> 19461650 | D11: =+Triangulo1!D82 -> 47069939 | E11: =+'1_CL'!W32 -> 0.99999718 | F11: =1-E11 -> 2.8220216e-06 | G11: =+$B$4*D11 -> 25888467 | H11: =+G11*F11 -> 73.057811 | I11: =+H11+C11 -> 19461723
A12: AO005 | B12: 1Q20 | C12: =+Triangulo1!E83 -> 11816173 | D12: =+Triangulo1!D83 -> 10724971 | E12: =+'1_CL'!V32 -> 0.99999415 | F12: =1-E12 -> 5.8469023e-06 | G12: =+$B$4*D12 -> 5898734 | H12: =+G12*F12 -> 34.489321 | I12: =+H12+C12 -> 11816207
A13: AO006 | B13: 2Q20 | C13: =+Triangulo1!E84 -> 13048471 | D13: =+Triangulo1!D84 -> 19800249 | E13: =+'1_CL'!U32 -> 0.99998445 | F13: =1-E13 -> 1.5553276e-05 | G13: =+$B$4*D13 -> 10890137 | H13: =+G13*F13 -> 169.37731 | I13: =+H13+C13 -> 13048640
A14: AO007 | B14: 3Q20 | C14: =+Triangulo1!E85 -> 10840140 | D14: =+Triangulo1!D85 -> 28289118 | E14: =+'1_CL'!T32 -> 0.99995183 | F14: =1-E14 -> 4.8168928e-05 | G14: =+$B$4*D14 -> 15559015 | H14: =+G14*F14 -> 749.46108 | I14: =+H14+C14 -> 10840889
A15: AO008 | B15: 4Q20 | C15: =+Triangulo1!E86 -> 14111136 | D15: =+Triangulo1!D86 -> 30704506 | E15: =+'1_CL'!S32 -> 0.99988291 | F15: =1-E15 -> 0.0001170868 | G15: =+$B$4*D15 -> 16887478 | H15: =+G15*F15 -> 1977.3008 | I15: =+H15+C15 -> 14113113
A16: AO009 | B16: 1Q21 | C16: =+Triangulo1!E87 -> 15729334 | D16: =+Triangulo1!D87 -> 18880428 | E16: =+'1_CL'!R32 -> 0.99974292 | F16: =1-E16 -> 0.00025707663 | G16: =+$B$4*D16 -> 10384236 | H16: =+G16*F16 -> 2669.5443 | I16: =+H16+C16 -> 15732004
A17: AO010 | B17: 2Q21 | C17: =+Triangulo1!E88 -> 14343596 | D17: =+Triangulo1!D88 -> 17119243 | E17: =+'1_CL'!Q32 -> 0.99943548 | F17: =1-E17 -> 0.00056451736 | G17: =+$B$4*D17 -> 9415583.8 | H17: =+G17*F17 -> 5315.2605 | I17: =+H17+C17 -> 14348911
A18: AO011 | B18: 3Q21 | C18: =+Triangulo1!E89 -> 15119935 | D18: =+Triangulo1!D89 -> 41471482 | E18: =+'1_CL'!P32 -> 0.99884713 | F18: =1-E18 -> 0.0011528692 | G18: =+$B$4*D18 -> 22809315 | H18: =+G18*F18 -> 26296.157 | I18: =+H18+C18 -> 15146231
A19: AO012 | B19: 4Q21 | C19: =+Triangulo1!E90 -> 18730024 | D19: =+Triangulo1!D90 -> 35368087 | E19: =+'1_CL'!O32 -> 0.99771363 | F19: =1-E19 -> 0.0022863652 | G19: =+$B$4*D19 -> 19452448 | H19: =+G19*F19 -> 44475.4 | I19: =+H19+C19 -> 18774499
A20: AO013 | B20: 1Q22 | C20: =+Triangulo1!E91 -> 19627354 | D20: =+Triangulo1!D91 -> 26145160 | E20: =+'1_CL'!N32 -> 0.99547136 | F20: =1-E20 -> 0.0045286435 | G20: =+$B$4*D20 -> 14379838 | H20: =+G20*F20 -> 65121.159 | I20: =+H20+C20 -> 19692475
A21: AO014 | B21: 2Q22 | C21: =+Triangulo1!E92 -> 20049671 | D21: =+Triangulo1!D92 -> 46483439 | E21: =+'1_CL'!M32 -> 0.99164194 | F21: =1-E21 -> 0.0083580637 | G21: =+$B$4*D21 -> 25565891 | H21: =+G21*F21 -> 213681.35 | I21: =+H21+C21 -> 20263352
A22: AO015 | B22: 3Q22 | C22: =+Triangulo1!E93 -> 20688336 | D22: =+Triangulo1!D93 -> 28927094 | E22: =+'1_CL'!L32 -> 0.98367504 | F22: =1-E22 -> 0.016324962 | G22: =+$B$4*D22 -> 15909902 | H22: =+G22*F22 -> 259728.55 | I22: =+H22+C22 -> 20948065
A23: AO016 | B23: 4Q22 | C23: =+Triangulo1!E94 -> 25647723 | D23: =+Triangulo1!D94 -> 62474507 | E23: =+'1_CL'!K32 -> 0.96857859 | F23: =1-E23 -> 0.031421407 | G23: =+$B$4*D23 -> 34360979 | H23: =+G23*F23 -> 1079670.3 | I23: =+H23+C23 -> 26727393
A24: AO017 | B24: 1Q23 | C24: =+Triangulo1!E95 -> 26811464 | D24: =+Triangulo1!D95 -> 40231087 | E24: =+'1_CL'!J32 -> 0.94164172 | F24: =1-E24 -> 0.05835828 | G24: =+$B$4*D24 -> 22127098 | H24: =+G24*F24 -> 1291299.3 | I24: =+H24+C24 -> 28102763
A25: AO018 | B25: 2Q23 | C25: =+Triangulo1!E96 -> 21399003 | D25: =+Triangulo1!D96 -> 50080346 | E25: =+'1_CL'!I32 -> 0.8913332 | F25: =1-E25 -> 0.1086668 | G25: =+$B$4*D25 -> 27544190 | H25: =+G25*F25 -> 2993139.1 | I25: =+H25+C25 -> 24392142
A26: AO019 | B26: 3Q23 | C26: =+Triangulo1!E97 -> 33589263 | D26: =+Triangulo1!D97 -> 68225324 | E26: =+'1_CL'!H32 -> 0.80144236 | F26: =1-E26 -> 0.19855764 | G26: =+$B$4*D26 -> 37523928 | H26: =+G26*F26 -> 7450662.8 | I26: =+H26+C26 -> 41039926
A27: AO020 | B27: 4Q23 | C27: =+Triangulo1!E98 -> 21705785 | D27: =+Triangulo1!D98 -> 46727120 | E27: =+'1_CL'!G32 -> 0.72579635 | F27: =1-E27 -> 0.27420365 | G27: =+$B$4*D27 -> 25699916 | H27: =+G27*F27 -> 7047010.6 | I27: =+H27+C27 -> 28752796
A28: AO021 | B28: 1Q24 | C28: =+Triangulo1!E99 -> 17306094 | D28: =+Triangulo1!D99 -> 63421725 | E28: =+'1_CL'!F32 -> 0.62464486 | F28: =1-E28 -> 0.37535514 | G28: =+$B$4*D28 -> 34881949 | H28: =+G28*F28 -> 13093119 | I28: =+H28+C28 -> 30399213
A29: AO022 | B29: 2Q24 | C29: =+Triangulo1!E100 -> 15374462 | D29: =+Triangulo1!D100 -> 44130894 | E29: =+'1_CL'!E32 -> 0.50138363 | F29: =1-E29 -> 0.49861637 | G29: =+$B$4*D29 -> 24271992 | H29: =+G29*F29 -> 12102412 | I29: =+H29+C29 -> 27476874
A30: AO023 | B30: 3Q24 | C30: =+Triangulo1!E101 -> 9321834 | D30: =+Triangulo1!D101 -> 35850381 | E30: =+'1_CL'!D32 -> 0.3720834 | F30: =1-E30 -> 0.6279166 | G30: =+$B$4*D30 -> 19717709 | H30: =+G30*F30 -> 12381077 | I30: =+H30+C30 -> 21702911
A31: AO024 | B31: 4Q24 | C31: =+Triangulo1!E102 -> 5149958 | D31: =+Triangulo1!D102 -> 55736823 | E31: =+'1_CL'!C32 -> 0.17330594 | F31: =1-E31 -> 0.82669406 | G31: =+$B$4*D31 -> 30655252 | H31: =+G31*F31 -> 25342515 | I31: =+H31+C31 -> 30492473
A32: TOTAL | H32: =SUM(H8:H31) -> 83401232 | I32: =SUM(I8:I31) -> 4.9761506e+08

Sheet 1_CC
A1: CAPE COD · ELR_CC = Σ Pagados / Σ(Prima×%Des) · ELR endógeno calculado en B4
A2: ELR_CC en B4 calculado automáticamente · % Des de 4_BF · Primas de 1_Triangulo
A4: ELR Cape Cod: | B4: =SUM(C8:C31)/SUM(G8:G31) -> 0.55426932 | C4: Σ Pagados / Σ(Prima×%Des) — se actualiza automáticamente
A7: AO | B7: Trim. | C7: Pagado actual | D7: Prima Devengada | E7: % Des. | F7: % No-Des. | G7: Prima × %Des | H7: IBNR_CC =Prima×%NoDes×ELR_CC | I7: Último_CC
A8: =+'1_BF'!A8 -> AO001 | B8: =+'1_BF'!B8 -> 1Q19 | C8: =+'1_BF'!C8 -> 14725385 | D8: =+'1_BF'!D8 -> 30470484 | E8: =+'1_BF'!E8 -> 1 | F8: =1-E8 -> 0 | G8: =D8*E8 -> 30470484 | H8: =D8*F8*$B$4 -> 0 | I8: =C8+H8 -> 14725385
A9: =+'1_BF'!A9 -> AO002 | B9: =+'1_BF'!B9 -> 2Q19 | C9: =+'1_BF'!C9 -> 17735279 | D9: =+'1_BF'!D9 -> 35502400 | E9: =+'1_BF'!E9 -> 0.99999891 | F9: =1-E9 -> 1.086559e-06 | G9: =D9*E9 -> 35502361 | H9: =D9*F9*$B$4 -> 21.38119 | I9: =C9+H9 -> 17735300
A10: =+'1_BF'!A10 -> AO003 | B10: =+'1_BF'!B10 -> 3Q19 | C10: =+'1_BF'!C10 -> 11881761 | D10: =+'1_BF'!D10 -> 15118899 | E10: =+'1_BF'!E10 -> 0.99999833 | F10: =1-E10 -> 1.6718825e-06 | G10: =D10*E10 -> 15118874 | H10: =D10*F10*$B$4 -> 14.010278 | I10: =C10+H10 -> 11881775
A11: =+'1_BF'!A11 -> AO004 | B11: =+'1_BF'!B11 -> 4Q19 | C11: =+'1_BF'!C11 -> 19461650 | D11: =+'1_BF'!D11 -> 47069939 | E11: =+'1_BF'!E11 -> 0.99999718 | F11: =1-E11 -> 2.8220216e-06 | G11: =D11*E11 -> 47069806 | H11: =D11*F11*$B$4 -> 73.624914 | I11: =C11+H11 -> 19461724
A12: =+'1_BF'!A12 -> AO005 | B12: =+'1_BF'!B12 -> 1Q20 | C12: =+'1_BF'!C12 -> 11816173 | D12: =+'1_BF'!D12 -> 10724971 | E12: =+'1_BF'!E12 -> 0.99999415 | F12: =1-E12 -> 5.8469023e-06 | G12: =D12*E12 -> 10724908 | H12: =D12*F12*$B$4 -> 34.757041 | I12: =C12+H12 -> 11816208
A13: =+'1_BF'!A13 -> AO006 | B13: =+'1_BF'!B13 -> 2Q20 | C13: =+'1_BF'!C13 -> 13048471 | D13: =+'1_BF'!D13 -> 19800249 | E13: =+'1_BF'!E13 -> 0.99998445 | F13: =1-E13 -> 1.5553276e-05 | G13: =D13*E13 -> 19799941 | H13: =D13*F13*$B$4 -> 170.69208 | I13: =C13+H13 -> 13048642
A14: =+'1_BF'!A14 -> AO007 | B14: =+'1_BF'!B14 -> 3Q20 | C14: =+'1_BF'!C14 -> 10840140 | D14: =+'1_BF'!D14 -> 28289118 | E14: =+'1_BF'!E14 -> 0.99995183 | F14: =1-E14 -> 4.8168928e-05 | G14: =D14*E14 -> 28287756 | H14: =D14*F14*$B$4 -> 755.27869 | I14: =C14+H14 -> 10840895
A15: =+'1_BF'!A15 -> AO008 | B15: =+'1_BF'!B15 -> 4Q20 | C15: =+'1_BF'!C15 -> 14111136 | D15: =+'1_BF'!D15 -> 30704506 | E15: =+'1_BF'!E15 -> 0.99988291 | F15: =1-E15 -> 0.0001170868 | G15: =D15*E15 -> 30700911 | H15: =D15*F15*$B$4 -> 1992.6494 | I15: =C15+H15 -> 14113129
A16: =+'1_BF'!A16 -> AO009 | B16: =+'1_BF'!B16 -> 1Q21 | C16: =+'1_BF'!C16 -> 15729334 | D16: =+'1_BF'!D16 -> 18880428 | E16: =+'1_BF'!E16 -> 0.99974292 | F16: =1-E16 -> 0.00025707663 | G16: =D16*E16 -> 18875575 | H16: =D16*F16*$B$4 -> 2690.2664 | I16: =C16+H16 -> 15732024
A17: =+'1_BF'!A17 -> AO010 | B17: =+'1_BF'!B17 -> 2Q21 | C17: =+'1_BF'!C17 -> 14343596 | D17: =+'1_BF'!D17 -> 17119243 | E17: =+'1_BF'!E17 -> 0.99943548 | F17: =1-E17 -> 0.00056451736 | G17: =D17*E17 -> 17109579 | H17: =D17*F17*$B$4 -> 5356.5197 | I17: =C17+H17 -> 14348953
A18: =+'1_BF'!A18 -> AO011 | B18: =+'1_BF'!B18 -> 3Q21 | C18: =+'1_BF'!C18 -> 15119935 | D18: =+'1_BF'!D18 -> 41471482 | E18: =+'1_BF'!E18 -> 0.99884713 | F18: =1-E18 -> 0.0011528692 | G18: =D18*E18 -> 41423671 | H18: =D18*F18*$B$4 -> 26500.278 | I18: =C18+H18 -> 15146435
A19: =+'1_BF'!A19 -> AO012 | B19: =+'1_BF'!B19 -> 4Q21 | C19: =+'1_BF'!C19 -> 18730024 | D19: =+'1_BF'!D19 -> 35368087 | E19: =+'1_BF'!E19 -> 0.99771363 | F19: =1-E19 -> 0.0022863652 | G19: =D19*E19 -> 35287223 | H19: =D19*F19*$B$4 -> 44820.636 | I19: =C19+H19 -> 18774845
... A31: =+'1_BF'!A31 -> AO024 | B31: =+'1_BF'!B31 -> 4Q24 | C31: =+'1_BF'!C31 -> 5149958 | D31: =+'1_BF'!D31 -> 55736823 | E31: =+'1_BF'!E31 -> 0.17330594 | F31: =1-E31 -> 0.82669406 | G31: =D31*E31 -> 9659522.3 | H31: =D31*F31*$B$4 -> 25539234 | I31: =C31+H31 -> 30689192
A32: TOTAL | G32: =SUM(G8:G31) -> 7.473151e+08 | H32: =SUM(H8:H31) -> 84048625 | I32: =SUM(I8:I31) -> 4.9826246e+08

Sheet 1_Duration
B1: DURACIÓN DE CARTERA — AUTO DAÑOS / RC PERSONAL
B2: Metodología: Macaulay · Modificada · Efectiva | Fuente: D'Arcy & Gorvett (2000), PCAS | N2: Trimestral
N3: Anual
B4: PARÁMETROS DE ENTRADA | I4: Trimestral
B5: Reserva total (MXN) | C5: ='1_CL'!AC33 -> 88287626 | D5: Monto total de la reserva IBNR a valuar
B6: Tasa de descuento (r) | C6: =IF(I4="Anual",Triangulo1!E4, POWER(1+Triangulo1!E4,0.25)-1) -> 0.014673846 | D6: Tasa libre de riesgo (CETES / curva CNSF) | J6: 0.04
B7: Shock de tasa (Δr) | C7: 0.01 | D7: Desplazamiento para calcular duración efectiva (±100 bps)
B8: Correlación tasas-inflación | C8: 0.4 | D8: ρ: usada para ajustar D_Efectiva (D'Arcy 2000, Tabla 3)
B10: A. PATRÓN DE DESARROLLO Y FLUJOS DE PAGO
B11: Trimestre (t) | C11: % Pago Acumulado | D11: % Pago Incremental | E11: Flujo Nominal (MXN) | F11: PV del Flujo (MXN) | G11: Peso = PV/PV_Total | H11: t × Peso | I11: t(t+1)×PV/(1+r)² (Convexidad)
B12: =IF(I4= "Anual",1,0.25) -> 0.25 | C12: ='1_BF'!E31 -> 0.17330594 | D12: =C12 -> 0.17330594 | E12: =D12*$C$5 -> 15300770 | F12: =IF($I$4="Anual",E12/(1+$C$6)^B12,E12/(1+$C$6)^(B12*4)) -> 15079496 | G12: =F12/$F$36 -> 0.18100643 | H12: =B12*G12 -> 0.045251607 | I12: =B12*(B12+1)*F12/((1+$C$6)^2)/$F$36 -> 0.054940308 | J12: =+B12*F12 -> 3769873.9
B13: =IF($I$4="Anual",B12+1,B12+0.25) -> 0.5 | C13: ='1_BF'!E30 -> 0.3720834 | D13: =C13-C12 -> 0.19877746 | E13: =D13*$C$5 -> 17549590 | F13: =IF($I$4="Anual",E13/(1+$C$6)^B13,E13/(1+$C$6)^(B13*4)) -> 17045669 | G13: =F13/$F$36 -> 0.20460735 | H13: =B13*G13 -> 0.10230367 | I13: =B13*(B13+1)*F13/((1+$C$6)^2)/$F$36 -> 0.14904917 | J13: =+B13*F13 -> 8522834.3
B14: =IF($I$4="Anual",B13+1,B13+0.25) -> 0.75 | C14: ='1_BF'!E29 -> 0.50138363 | D14: =C14-C13 -> 0.12930024 | E14: =D14*$C$5 -> 11415611 | F14: =IF($I$4="Anual",E14/(1+$C$6)^B14,E14/(1+$C$6)^(B14*4)) -> 10927473 | G14: =F14/$F$36 -> 0.13116771 | H14: =B14*G14 -> 0.098375783 | I14: =B14*(B14+1)*F14/((1+$C$6)^2)/$F$36 -> 0.16721426 | J14: =+B14*F14 -> 8195605
B15: =IF($I$4="Anual",B14+1,B14+0.25) -> 1 | C15: ='1_BF'!E28 -> 0.62464486 | D15: =C15-C14 -> 0.12326123 | E15: =D15*$C$5 -> 10882441 | F15: =IF($I$4="Anual",E15/(1+$C$6)^B15,E15/(1+$C$6)^(B15*4)) -> 10266454 | G15: =F15/$F$36 -> 0.12323318 | H15: =B15*G15 -> 0.12323318 | I15: =B15*(B15+1)*F15/((1+$C$6)^2)/$F$36 -> 0.23938928 | J15: =+B15*F15 -> 10266454
B16: =IF($I$4="Anual",B15+1,B15+0.25) -> 1.25 | C16: ='1_BF'!E27 -> 0.72579635 | D16: =C16-C15 -> 0.1011515 | E16: =D16*$C$5 -> 8930425.5 | F16: =IF($I$4="Anual",E16/(1+$C$6)^B16,E16/(1+$C$6)^(B16*4)) -> 8303091.5 | G16: =F16/$F$36 -> 0.099665995 | H16: =B16*G16 -> 0.12458249 | I16: =B16*(B16+1)*F16/((1+$C$6)^2)/$F$36 -> 0.27226173 | J16: =+B16*F16 -> 10378864
B17: =IF($I$4="Anual",B16+1,B16+0.25) -> 1.5 | C17: ='1_BF'!E26 -> 0.80144236 | D17: =C17-C16 -> 0.075646002 | E17: =D17*$C$5 -> 6678606 | F17: =IF($I$4="Anual",E17/(1+$C$6)^B17,E17/(1+$C$6)^(B17*4)) -> 6119656.2 | G17: =F17/$F$36 -> 0.073457172 | H17: =B17*G17 -> 0.11018576 | I17: =B17*(B17+1)*F17/((1+$C$6)^2)/$F$36 -> 0.26755467 | J17: =+B17*F17 -> 9179484.3
B18: =IF($I$4="Anual",B17+1,B17+0.25) -> 1.75 | C18: ='1_BF'!E25 -> 0.8913332 | D18: =C18-C17 -> 0.089890842 | E18: =D18*$C$5 -> 7936249 | F18: =IF($I$4="Anual",E18/(1+$C$6)^B18,E18/(1+$C$6)^(B18*4)) -> 7166878.2 | G18: =F18/$F$36 -> 0.086027481 | H18: =B18*G18 -> 0.15054809 | I18: =B18*(B18+1)*F18/((1+$C$6)^2)/$F$36 -> 0.40211939 | J18: =+B18*F18 -> 12542037
B19: =IF($I$4="Anual",B18+1,B18+0.25) -> 2 | C19: ='1_BF'!E24 -> 0.94164172 | D19: =C19-C18 -> 0.050308522 | E19: =D19*$C$5 -> 4441619.9 | F19: =IF($I$4="Anual",E19/(1+$C$6)^B19,E19/(1+$C$6)^(B19*4)) -> 3953025.9 | G19: =F19/$F$36 -> 0.047450069 | H19: =B19*G19 -> 0.094900138 | I19: =B19*(B19+1)*F19/((1+$C$6)^2)/$F$36 -> 0.27652549 | J19: =+B19*F19 -> 7906051.9
B20: =IF($I$4="Anual",B19+1,B19+0.25) -> 2.25 | C20: ='1_BF'!E23 -> 0.96857859 | D20: =C20-C19 -> 0.026936872 | E20: =D20*$C$5 -> 2378192.5 | F20: =IF($I$4="Anual",E20/(1+$C$6)^B20,E20/(1+$C$6)^(B20*4)) -> 2085973.6 | G20: =F20/$F$36 -> 0.025038943 | H20: =B20*G20 -> 0.056337622 | I20: =B20*(B20+1)*F20/((1+$C$6)^2)/$F$36 -> 0.17783979 | J20: =+B20*F20 -> 4693440.6
B21: =IF($I$4="Anual",B20+1,B20+0.25) -> 2.5 | C21: ='1_BF'!E22 -> 0.98367504 | D21: =C21-C20 -> 0.015096445 | E21: =D21*$C$5 -> 1332829.3 | F21: =IF($I$4="Anual",E21/(1+$C$6)^B21,E21/(1+$C$6)^(B21*4)) -> 1152152.2 | G21: =F21/$F$36 -> 0.013829837 | H21: =B21*G21 -> 0.034574592 | I21: =B21*(B21+1)*F21/((1+$C$6)^2)/$F$36 -> 0.11753634 | J21: =+B21*F21 -> 2880380.6
B22: =IF($I$4="Anual",B21+1,B21+0.25) -> 2.75 | C22: ='1_BF'!E21 -> 0.99164194 | D22: =C22-C21 -> 0.0079668985 | E22: =D22*$C$5 -> 703378.55 | F22: =IF($I$4="Anual",E22/(1+$C$6)^B22,E22/(1+$C$6)^(B22*4)) -> 599236.13 | G22: =F22/$F$36 -> 0.0071929191 | H22: =B22*G22 -> 0.019780528 | I22: =B22*(B22+1)*F22/((1+$C$6)^2)/$F$36 -> 0.07204705 | J22: =+B22*F22 -> 1647899.4
B23: =IF($I$4="Anual",B22+1,B22+0.25) -> 3 | C23: ='1_BF'!E20 -> 0.99547136 | D23: =C23-C22 -> 0.0038294202 | E23: =D23*$C$5 -> 338090.42 | F23: =IF($I$4="Anual",E23/(1+$C$6)^B23,E23/(1+$C$6)^(B23*4)) -> 283867.24 | G23: =F23/$F$36 -> 0.0034073948 | H23: =B23*G23 -> 0.010222184 | I23: =B23*(B23+1)*F23/((1+$C$6)^2)/$F$36 -> 0.039714652 | J23: =+B23*F23 -> 851601.71
B24: =IF($I$4="Anual",B23+1,B23+0.25) -> 3.25 | C24: ='1_BF'!E19 -> 0.99771363 | D24: =C24-C23 -> 0.0022422783 | E24: =D24*$C$5 -> 197965.42 | F24: =IF($I$4="Anual",E24/(1+$C$6)^B24,E24/(1+$C$6)^(B24*4)) -> 163811.84 | G24: =F24/$F$36 -> 0.0019663122 | H24: =B24*G24 -> 0.0063905145 | I24: =B24*(B24+1)*F24/((1+$C$6)^2)/$F$36 -> 0.02637982 | J24: =+B24*F24 -> 532388.47
B25: =IF($I$4="Anual",B24+1,B24+0.25) -> 3.5 | C25: ='1_BF'!E18 -> 0.99884713 | D25: =C25-C24 -> 0.001133496 | E25: =D25*$C$5 -> 100073.67 | F25: =IF($I$4="Anual",E25/(1+$C$6)^B25,E25/(1+$C$6)^(B25*4)) -> 81611.114 | G25: =F25/$F$36 -> 0.0009796174 | H25: =B25*G25 -> 0.0034286609 | I25: =B25*(B25+1)*F25/((1+$C$6)^2)/$F$36 -> 0.014985944 | J25: =+B25*F25 -> 285638.9
B26: =IF($I$4="Anual",B25+1,B25+0.25) -> 3.75 | C26: ='1_BF'!E17 -> 0.99943548 | D26: =C26-C25 -> 0.00058835183 | E26: =D26*$C$5 -> 51944.187 | F26: =IF($I$4="Anual",E26/(1+$C$6)^B26,E26/(1+$C$6)^(B26*4)) -> 41748.411 | G26: =F26/$F$36 -> 0.00050112623 | H26: =B26*G26 -> 0.0018792234 | I26: =B26*(B26+1)*F26/((1+$C$6)^2)/$F$36 -> 0.0086699997 | J26: =+B26*F26 -> 156556.54
B27: =IF($I$4="Anual",B26+1,B26+0.25) -> 4 | C27: ='1_BF'!E16 -> 0.99974292 | D27: =C27-C26 -> 0.00030744072 | E27: =D27*$C$5 -> 27143.212 | F27: =IF($I$4="Anual",E27/(1+$C$6)^B27,E27/(1+$C$6)^(B27*4)) -> 21499.966 | G27: =F27/$F$36 -> 0.00025807442 | H27: =B27*G27 -> 0.0010322977 | I27: =B27*(B27+1)*F27/((1+$C$6)^2)/$F$36 -> 0.0050132807 | J27: =+B27*F27 -> 85999.864
B28: =IF($I$4="Anual",B27+1,B27+0.25) -> 4.25 | C28: ='1_BF'!E15 -> 0.99988291 | D28: =C28-C27 -> 0.00013998983 | E28: =D28*$C$5 -> 12359.37 | F28: =IF($I$4="Anual",E28/(1+$C$6)^B28,E28/(1+$C$6)^(B28*4)) -> 9648.2025 | G28: =F28/$F$36 -> 0.00011581201 | H28: =B28*G28 -> 0.00049220104 | I28: =B28*(B28+1)*F28/((1+$C$6)^2)/$F$36 -> 0.0025098565 | J28: =+B28*F28 -> 41004.861
B29: =IF($I$4="Anual",B28+1,B28+0.25) -> 4.5 | C29: ='1_BF'!E14 -> 0.99995183 | D29: =C29-C28 -> 6.8917872e-05 | E29: =D29*$C$5 -> 6084.5953 | F29: =IF($I$4="Anual",E29/(1+$C$6)^B29,E29/(1+$C$6)^(B29*4)) -> 4681.1796 | G29: =F29/$F$36 -> 5.6190447e-05 | H29: =B29*G29 -> 0.00025285701 | I29: =B29*(B29+1)*F29/((1+$C$6)^2)/$F$36 -> 0.0013507804 | J29: =+B29*F29 -> 21065.308
B30: =IF($I$4="Anual",B29+1,B29+0.25) -> 4.75 | C30: ='1_BF'!E13 -> 0.99998445 | D30: =C30-C29 -> 3.2615652e-05 | E30: =D30*$C$5 -> 2879.5585 | F30: =IF($I$4="Anual",E30/(1+$C$6)^B30,E30/(1+$C$6)^(B30*4)) -> 2183.3484 | G30: =F30/$F$36 -> 2.6207779e-05 | H30: =B30*G30 -> 0.00012448695 | I30: =B30*(B30+1)*F30/((1+$C$6)^2)/$F$36 -> 0.00069524639 | J30: =+B30*F30 -> 10370.905
B31: =IF($I$4="Anual",B30+1,B30+0.25) -> 5 | C31: ='1_BF'!E12 -> 0.99999415 | D31: =C31-C30 -> 9.7063741e-06 | E31: =D31*$C$5 -> 856.95272 | F31: =IF($I$4="Anual",E31/(1+$C$6)^B31,E31/(1+$C$6)^(B31*4)) -> 640.36493 | G31: =F31/$F$36 -> 7.6866078e-06 | H31: =B31*G31 -> 3.8433039e-05 | I31: =B31*(B31+1)*F31/((1+$C$6)^2)/$F$36 -> 0.0002239768 | J31: =+B31*F31 -> 3201.8246
B32: =IF($I$4="Anual",B31+1,B31+0.25) -> 5.25 | C32: ='1_BF'!E11 -> 0.99999718 | D32: =C32-C31 -> 3.0248807e-06 | E32: =D32*$C$5 -> 267.05954 | F32: =IF($I$4="Anual",E32/(1+$C$6)^B32,E32/(1+$C$6)^(B32*4)) -> 196.67642 | G32: =F32/$F$36 -> 2.3608016e-06 | H32: =B32*G32 -> 1.2394208e-05 | I32: =B32*(B32+1)*F32/((1+$C$6)^2)/$F$36 -> 7.5239495e-05 | J32: =+B32*F32 -> 1032.5512
B33: =IF($I$4="Anual",B32+1,B32+0.25) -> 5.5 | C33: ='1_BF'!E10 -> 0.99999833 | D33: =C33-C32 -> 1.1501391e-06 | E33: =D33*$C$5 -> 101.54305 | F33: =IF($I$4="Anual",E33/(1+$C$6)^B33,E33/(1+$C$6)^(B33*4)) -> 73.700075 | G33: =F33/$F$36 -> 8.846574e-07 | H33: =B33*G33 -> 4.8656157e-06 | I33: =B33*(B33+1)*F33/((1+$C$6)^2)/$F$36 -> 3.0718374e-05 | J33: =+B33*F33 -> 405.35041
B34: =IF($I$4="Anual",B33+1,B33+0.25) -> 5.75 | C34: ='1_BF'!E9 -> 0.99999891 | D34: =C34-C33 -> 5.8532348e-07 | E34: =D34*$C$5 -> 51.67682 | F34: =IF($I$4="Anual",E34/(1+$C$6)^B34,E34/(1+$C$6)^(B34*4)) -> 36.964689 | G34: =F34/$F$36 -> 4.4370492e-07 | H34: =B34*G34 -> 2.5513033e-06 | I34: =B34*(B34+1)*F34/((1+$C$6)^2)/$F$36 -> 1.6726802e-05 | J34: =+B34*F34 -> 212.54696
B35: =IF($I$4="Anual",B34+1,B34+0.25) -> 6 | C35: ='1_BF'!E8 -> 1 | D35: =C35-C34 -> 1.086559e-06 | E35: =D35*$C$5 -> 95.929717 | F35: =IF($I$4="Anual",E35/(1+$C$6)^B35,E35/(1+$C$6)^(B35*4)) -> 67.626665 | G35: =F35/$F$36 -> 8.1175534e-07 | H35: =B35*G35 -> 4.8705321e-06 | I35: =B35*(B35+1)*F35/((1+$C$6)^2)/$F$36 -> 3.3114752e-05 | J35: =+B35*F35 -> 405.75999
B36: TOTAL | C36: 100.00% | D36: =SUM(D12:D35) -> 1 | E36: =SUM(E12:E35) -> 88287626 | F36: =SUM(F12:F35) -> 83309172 | G36: =SUM(G12:G35) -> 1 | H36: =SUM(H12:H35) -> 0.983959 | I36: =SUM(I12:I35) -> 2.2961768 | J36: =SUM(J12:J35) -> 81972809 | K36: =+J36/F36 -> 0.983959
F37: 895587.34
B38: B. CÁLCULO DE DURACIÓN
B39: Duración de Macaulay (D_Mac) | C39: =SUMPRODUCT(B12:B35,F12:F35)/F36 -> 0.983959 | D39: años | E39: D_Mac = Σ[t × PV(CF_t)] / PV_Total | H39: ~0.98 años
B41: Duración Modificada (D_Mod) | C41: =(SUMPRODUCT(B12:B35,F12:F35)/F36)/(1+Triangulo1!E4) -> 0.92826321 | D41: años | E41: D_Mod = D_Mac / (1 + r) | H41: ~0.92 años
B43: Convexidad | C43: {=SUMPRODUCT(B12:B35*(B12:B35+1),F12:F35)/((1+Triangulo1!E4)^2*F36)} -> 2.1040039 | E43: Conv = Σ[t(t+1)×PV(CF_t)/PV_Total] / (1+r)² | H43: Curvatura de la función PV vs tasa
...

Sheet 1_Validacion_BT
A1: VALIDACIÓN DE TRIÁNGULOS Y BACKTESTING
A3: A — MONOTONICIDAD ratio_{i,j} = C_{i,j+1}/C_{i,j} ≥ 1.0
A4: Año | B4: D1/D0 | C4: D2/D1 | D4: D3/D2 | E4: D4/D3 | F4: D5/D4 | G4: D6/D5 | H4: D7/D6 | I4: D8/D7 | J4: D9/D8 | K4: D10/D9 | L4: D11/D10 | M4: D12/D11 | N4: D13/D12 | O4: D14/D13 | P4: D15/D14 | Q4: D16/D15 | R4: D17/D16 | S4: D18/D17 | T4: D19/D18 | U4: D20/D19 | V4: D21/D20 | W4: D22/D21 | X4: D23/D22 | Y4: ¿Monótono? (todos ≥1?) | Z4: ¿Outlier? | AC4: D1/D0 | AD4: D2/D1 | AE4: D3/D2 | AF4: D4/D3 | AG4: D5/D4 | AH4: D6/D5 | AI4: D7/D6 | AJ4: D8/D7 | AK4: D9/D8 | AL4: D10/D9 | AM4: D11/D10 | AN4: D12/D11 | AO4: D13/D12 | AP4: D14/D13 | AQ4: D15/D14 | AR4: D16/D15 | AS4: D17/D16 | AT4: D18/D17 | AU4: D19/D18 | AV4: D20/D19 | AW4: D21/D20 | AX4: D22/D21 | AY4: D23/D22
A5: 1Q19 | B5: =Triangulo1!D44 -> 1.3012916 | C5: =Triangulo1!E44 -> 1.1246587 | D5: =Triangulo1!F44 -> 1.1905767 | E5: =Triangulo1!G44 -> 1.0820522 | F5: =Triangulo1!H44 -> 1.0512626 | G5: =Triangulo1!I44 -> 1.0277185 | H5: =Triangulo1!J44 -> 1.0363301 | I5: =Triangulo1!K44 -> 1.0133706 | ... X5: =Triangulo1!Z44 -> 1.0000011 | Y5: =MIN(B5:X5)>1 -> TRUE | Z5: {=MAX(ABS(AC5:AC26))>0.1} -> TRUE | AC5: =(B5-B6)/B5 -> -0.074196974 | AD5: =(C5-C6)/C5 -> -0.064916125 | AE5: =(D5-D6)/D5 -> 0.11754669 | AF5: =(E5-E6)/E5 -> -0.013314885 | AG5: =(F5-F6)/F5 -> 0.00076145876 | AH5: =(G5-G6)/G5 -> -0.026145173 | AI5: =(H5-H6)/H5 -> 0.0066497824 | AJ5: =(I5-I6)/I5 -> -0.0059993053 | ... AX5: =(W5-W6)/W5 -> -7.6952645e-08
A6: 2Q19 | B6: =Triangulo1!D45 -> 1.3978435 | C6: =Triangulo1!E45 -> 1.1976672 | D6: =Triangulo1!F45 -> 1.0506283 | E6: =Triangulo1!G45 -> 1.0964596 | F6: =Triangulo1!H45 -> 1.0504621 | G6: =Triangulo1!I45 -> 1.0545884 | H6: =Triangulo1!J45 -> 1.0294387 | I6: =Triangulo1!K45 -> 1.0194501 | ... X6: =Triangulo1!Z45 -> 0 | Y6: =MIN(B6:W6)>1 -> TRUE | Z6: {=MAX(ABS(AD5:AD25))>0.1} -> TRUE | AC6: =(B6-B7)/B6 -> 0.18227943 | AD6: =(C6-C7)/C6 -> 0.024442003 | AE6: =(D6-D7)/D6 -> -0.099418071 | AF6: =(E6-E7)/E6 -> -0.016706695 | AG6: =(F6-F7)/F6 -> -0.084500941 | AH6: =(G6-G7)/G6 -> -0.011068746 | AI6: =(H6-H7)/H6 -> -0.0067850143 | AJ6: =(I6-I7)/I6 -> -0.0085836249 | ... AW6: =(V6-V7)/V6 -> -2.4660131e-06
A7: 3Q19 | B7: =Triangulo1!D46 -> 1.1430454 | C7: =Triangulo1!E46 -> 1.1683938 | D7: =Triangulo1!F46 -> 1.1550798 | E7: =Triangulo1!G46 -> 1.1147778 | F7: =Triangulo1!H46 -> 1.1392271 | G7: =Triangulo1!I46 -> 1.0662613 | H7: =Triangulo1!J46 -> 1.0364235 | I7: =Triangulo1!K46 -> 1.0282007 | ... X7: =Triangulo1!Z46 -> 0 | Y7: =MIN(B7:V7)>1 -> TRUE | Z7: {=MAX(ABS(AE5:AE26))>0.1} -> TRUE | AC7: =(B7-B8)/B7 -> -0.89708106 | AD7: =(C7-C8)/C7 -> 0.025255445 | AE7: =(D7-D8)/D7 -> 0.089591929 | AF7: =(E7-E8)/E7 -> 0.037251974 | AG7: =(F7-F8)/F7 -> 0.075266535 | AH7: =(G7-G8)/G7 -> 0.047882161 | AI7: =(H7-H8)/H7 -> 0.018779326 | AJ7: =(I7-I8)/I7 -> -0.0041649243 | ... AV7: =(U7-U8)/U7 -> 9.8798353e-06
A8: 4Q19 | B8: =Triangulo1!D47 -> 2.1684497 | C8: =Triangulo1!E47 -> 1.1388855 | D8: =Triangulo1!F47 -> 1.051594 | E8: =Triangulo1!G47 -> 1.0732502 | F8: =Triangulo1!H47 -> 1.0534814 | G8: =Triangulo1!I47 -> 1.0152064 | H8: =Triangulo1!J47 -> 1.0169602 | I8: =Triangulo1!K47 -> 1.0324831 | ... X8: =Triangulo1!Z47 -> 0 | Y8: =MIN(B8:U8)>1 -> TRUE | Z8: {=MAX(ABS(AF5:AF26))>0.1} -> TRUE | AC8: =(B8-B9)/B8 -> 0.4542195 | AD8: =(C8-C9)/C8 -> -0.01040957 | AE8: =(D8-D9)/D8 -> -0.003797103 | AF8: =(E8-E9)/E8 -> -0.020630915 | AG8: =(F8-F9)/F8 -> 0.0183154 | AH8: =(G8-G9)/G8 -> -0.049603577 | AI8: =(H8-H9)/H8 -> -0.015047799 | AJ8: =(I8-I9)/I8 -> 0.017987987 | ... AU8: =(T8-T9)/T8 -> -1.0524409e-05
A9: 1Q20 | B9: =Triangulo1!D48 -> 1.1834976 | C9: =Triangulo1!E48 -> 1.1507408 | D9: =Triangulo1!F48 -> 1.055587 | E9: =Triangulo1!G48 -> 1.0953923 | F9: =Triangulo1!H48 -> 1.0341865 | G9: =Triangulo1!I48 -> 1.0655643 | H9: =Triangulo1!J48 -> 1.0322632 | I9: =Triangulo1!K48 -> 1.0139108 | ... X9: =Triangulo1!Z48 -> 0 | Y9: =MIN(B9:T9)>1 -> TRUE | Z9: {=MAX(ABS(AG5:AG26))>0.1} -> TRUE | AC9: =(B9-B10)/B9 -> -0.22672537 | AD9: =(C9-C10)/C9 -> -0.029160437 | AE9: =(D9-D10)/D9 -> -0.0099285929 | AF9: =(E9-E10)/E9 -> -0.044871881 | AG9: =(F9-F10)/F9 -> -0.12569311 | AH9: =(G9-G10)/G9 -> 0.0061086925 | AI9: =(H9-H10)/H9 -> -0.28872894 | AJ9: =(I9-I10)/I9 -> -0.035662546 | ... AT9: =(S9-S10)/S9 -> 9.962348e-07
A10: 2Q20 | B10: =Triangulo1!D49 -> 1.4518265 | C10: =Triangulo1!E49 -> 1.1842969 | D10: =Triangulo1!F49 -> 1.0660675 | E10: =Triangulo1!G49 -> 1.1445446 | F10: =Triangulo1!H49 -> 1.1641766 | G10: =Triangulo1!I49 -> 1.0590551 | H10: =Triangulo1!J49 -> 1.3303074 | I10: =Triangulo1!K49 -> 1.0500694 | ... X10: =Triangulo1!Z49 -> 0 | Y10: =MIN(B10:S10)>1 -> TRUE | Z10: {=MAX(ABS(AH5:AH26))>0.1} -> TRUE | AC10: =(B10-B11)/B10 -> 0.056067889 | AD10: =(C10-C11)/C10 -> 0.03082674 | AE10: =(D10-D11)/D10 -> -0.12310941 | AF10: =(E10-E11)/E10 -> 0.09048745 | AG10: =(F10-F11)/F10 -> 0.11889836 | AH10: =(G10-G11)/G10 -> -0.028740208 | AI10: =(H10-H11)/H10 -> 0.20625639 | AJ10: =(I10-I11)/I10 -> -0.0023919515 | ... AS10: =(R10-R11)/R10 -> -1.7585368e-05
A11: 3Q20 | B11: =Triangulo1!D50 -> 1.3704256 | C11: =Triangulo1!E50 -> 1.1477889 | D11: =Triangulo1!F50 -> 1.1973104 | E11: =Triangulo1!G50 -> 1.0409777 | F11: =Triangulo1!H50 -> 1.0257579 | G11: =Triangulo1!I50 -> 1.0894926 | H11: =Triangulo1!J50 -> 1.055923 | I11: =Triangulo1!K50 -> 1.0525811 | ... X11: =Triangulo1!Z50 -> 0 | Y11: =MIN(B11:R11)>1 -> TRUE | Z11: {=MAX(ABS(AI5:AI26))>0.1} -> TRUE | AC11: =(B11-B12)/B11 -> -0.012892695 | AD11: =(C11-C12)/C11 -> 0.059560537 | AE11: =(D11-D12)/D11 -> 0.042328373 | AF11: =(E11-E12)/E11 -> -0.00026531237 | AG11: =(F11-F12)/F11 -> -0.028992225 | AH11: =(G11-G12)/G11 -> 0.054571649 | AI11: =(H11-H12)/H11 -> 0.008701621 | AJ11: =(I11-I12)/I11 -> 0.038115379 | ... AR11: =(Q11-Q12)/Q11 -> 9.1867768e-05
A12: 4Q20 | B12: =Triangulo1!D51 -> 1.3880941 | C12: =Triangulo1!E51 -> 1.079426 | D12: =Triangulo1!F51 -> 1.1466302 | E12: =Triangulo1!G51 -> 1.0412539 | F12: =Triangulo1!H51 -> 1.0554969 | G12: =Triangulo1!I51 -> 1.0300372 | H12: =Triangulo1!J51 -> 1.0467348 | I12: =Triangulo1!K51 -> 1.0124616 | ... X12: =Triangulo1!Z51 -> 0 | Y12: =MIN(B12:Q12)>1 -> TRUE | Z12: {=MAX(ABS(AJ5:AJ26))>0.1} -> FALSE | AC12: =(B12-B13)/B12 -> -0.039387649 | AD12: =(C12-C13)/C12 -> -0.12621299 | AE12: =(D12-D13)/D12 -> 0.025337433 | AF12: =(E12-E13)/E12 -> 0.0073460979 | AG12: =(F12-F13)/F12 -> -0.019765397 | AH12: =(G12-G13)/G12 -> 0.013541811 | AI12: =(H12-H13)/H12 -> -0.0066009378 | AJ12: =(I12-I13)/I12 -> -0.024021528 | ... AQ12: =(P12-P13)/P12 -> 8.3909254e-05
A13: 1Q21 | B13: =Triangulo1!D52 -> 1.4427679 | C13: =Triangulo1!E52 -> 1.2156636 | D13: =Triangulo1!F52 -> 1.1175775 | E13: =Triangulo1!G52 -> 1.0336047 | F13: =Triangulo1!H52 -> 1.0763592 | G13: =Triangulo1!I52 -> 1.0160886 | H13: =Triangulo1!J52 -> 1.0536442 | I13: =Triangulo1!K52 -> 1.0367825 | ... X13: =Triangulo1!Z52 -> 0 | Y13: =MIN(B13:P13)>1 -> TRUE | Z13: {=MAX(ABS(AK5:AK26))>0.1} -> FALSE | AC13: =(B13-B14)/B13 -> -0.024858598 | AD13: =(C13-C14)/C13 -> -0.003120953 | AE13: =(D13-D14)/D13 -> -0.042055781 | AF13: =(E13-E14)/E13 -> -0.032112796 | AG13: =(F13-F14)/F13 -> 0.017875512 | AH13: =(G13-G14)/G13 -> -0.027833127 | AI13: =(H13-H14)/H13 -> -0.031639031 | AJ13: =(I13-I14)/I13 -> -0.0042929004 | ... AP13: =(O13-O14)/O13 -> -5.0972301e-05
A14: 2Q21 | B14: =Triangulo1!D53 -> 1.4786331 | C14: =Triangulo1!E53 -> 1.2194576 | D14: =Triangulo1!F53 -> 1.1645781 | E14: =Triangulo1!G53 -> 1.0667967 | F14: =Triangulo1!H53 -> 1.0571188 | G14: =Triangulo1!I53 -> 1.0443695 | H14: =Triangulo1!J53 -> 1.0869805 | I14: =Triangulo1!K53 -> 1.0412333 | ... X14: =Triangulo1!Z53 -> 0 | Y14: =MIN(B14:O14)>1 -> TRUE | Z14: {=MAX(ABS(AL5:AL26))>0.1} -> FALSE | AC14: =(B14-B15)/B14 -> 0.15477115 | AD14: =(C14-C15)/C14 -> 0.0056386284 | AE14: =(D14-D15)/D14 -> 0.10953102 | AF14: =(E14-E15)/E14 -> -0.055827615 | AG14: =(F14-F15)/F14 -> 0.021026369 | AH14: =(G14-G15)/G14 -> -0.10246031 | AI14: =(H14-H15)/H14 -> 0.005559951 | AJ14: =(I14-I15)/I14 -> 0.0067200416 | ... AO14: =(N14-N15)/N14 -> 0.00025172232
A15: 3Q21 | B15: =Triangulo1!D54 -> 1.2497833 | C15: =Triangulo1!E54 -> 1.2125815 | D15: =Triangulo1!F54 -> 1.0370207 | E15: =Triangulo1!G54 -> 1.1263534 | F15: =Triangulo1!H54 -> 1.0348914 | G15: =Triangulo1!I54 -> 1.1513759 | H15: =Triangulo1!J54 -> 1.0809369 | I15: =Triangulo1!K54 -> 1.0342361 | ... X15: =Triangulo1!Z54 -> 0 | Y15: =MIN(B15:N15)>1 -> TRUE | Z15: {=MAX(ABS(AM5:AM26))>0.1} -> FALSE | AC15: =(B15-B16)/B15 -> -0.1614505 | AD15: =(C15-C16)/C15 -> -0.0096873102 | AE15: =(D15-D16)/D15 -> -0.012495703 | AF15: =(E15-E16)/E15 -> 0.021485338 | AG15: =(F15-F16)/F15 -> -0.086319269 | AH15: =(G15-G16)/G15 -> 0.03515839 | AI15: =(H15-H16)/H15 -> 0.012192634 | AJ15: =(I15-I16)/I15 -> 0.0078240552 | ... AN15: =(M15-M16)/M15 -> 4.820052e-05
A16: 4Q21 | B16: =Triangulo1!D55 -> 1.4515615 | C16: =Triangulo1!E55 -> 1.2243282 | D16: =Triangulo1!F55 -> 1.049979 | E16: =Triangulo1!G55 -> 1.1021533 | F16: =Triangulo1!H55 -> 1.1242225 | G16: =Triangulo1!I55 -> 1.1108954 | H16: =Triangulo1!J55 -> 1.0677575 | I16: =Triangulo1!K55 -> 1.0261442 | ... X16: =Triangulo1!Z55 -> 0 | Y16: =MIN(B16:M16)>1 -> TRUE | Z16: {=MAX(ABS(AN5:AN26))>0.1} -> FALSE | AC16: =(B16-B17)/B16 -> -0.025991573 | AD16: =(C16-C17)/C16 -> 0.0084323865 | AE16: =(D16-D17)/D16 -> -0.093499205 | AF16: =(E16-E17)/E16 -> -0.11543023 | AG16: =(F16-F17)/F16 -> -0.030150627 | AH16: =(G16-G17)/G16 -> -0.020357074 | AI16: =(H16-H17)/H16 -> 0.0057159138 | AJ16: =(I16-I17)/I16 -> -0.0067165084 | ... AM16: =(L16-L17)/L16 -> -1.8166431e-05
A17: 1Q22 | B17: =Triangulo1!D56 -> 1.4892898 | C17: =Triangulo1!E56 -> 1.2140042 | D17: =Triangulo1!F56 -> 1.1481512 | E17: =Triangulo1!G56 -> 1.2293751 | F17: =Triangulo1!H56 -> 1.1581185 | G17: =Triangulo1!I56 -> 1.13351 | H17: =Triangulo1!J56 -> 1.0616542 | I17: =Triangulo1!K56 -> 1.0330363 | ... X17: =Triangulo1!Z56 -> 0 | Y17: =MIN(B17:L17)>1 -> TRUE | Z17: {=MAX(ABS(AO5:AO26))>0.1} -> FALSE | AC17: =(B17-B18)/B17 -> 0.057777745 | AD17: =(C17-C18)/C17 -> 0.097061028 | AE17: =(D17-D18)/D17 -> -0.26659574 | AF17: =(E17-E18)/E17 -> -0.023039574 | AG17: =(F17-F18)/F17 -> 0.035937694 | AH17: =(G17-G18)/G17 -> 0.0065227358 | AI17: =(H17-H18)/H17 -> 0.013104779 | AJ17: =(I17-I18)/I17 -> 0.0074860924 | ... AL17: =(K17-K18)/K17 -> 0.0011280879
