Workbook

Sheet 1_Triangulo
A1: TRIÁNGULO DE SINIESTRALIDAD ACUMULADA — TRIMESTRAL · Diagonal: Q4-2023 · Cifras en MXN
A2: RC Auto · 25 trimestres de ocurrencia (Q4-2017→Q4-2023) × 25 trimestres de desarrollo
A3: AO | B3: Trim. | C3: T01 | D3: T02 | E3: T03 | F3: T04 | G3: T05 | H3: T06 | I3: T07 | J3: T08 | K3: T09 | L3: T10 | M3: T11 | N3: T12 | O3: T13 | P3: T14 | Q3: T15 | R3: T16 | S3: T17 | T3: T18 | U3: T19 | V3: T20 | W3: T21 | X3: T22 | Y3: T23 | Z3: T24 | AA3: T25 | AB3: Prima Emitida | AC3: Prima Devengada
A4: AO01 | B4: Q4 2017 | C4: 8043230 | D4: 12749167 | E4: 16473151 | F4: 20490701 | G4: 23608335 | H4: 27627507 | I4: 32596498 | J4: 36181589 | K4: 37392902 | L4: 39642407 | M4: 41059821 | N4: 42891272 | O4: 44085473 | P4: 44497842 | Q4: 45568358 | R4: 46813892 | S4: 47246038 | T4: 47967056 | U4: 48296965 | V4: 48755419 | W4: 49303699 | X4: 49380886 | Y4: 49649946 | Z4: 49794831 | AA4: 49970260 | AB4: 73529411 | AC4: 74396187
A5: AO02 | B5: Q1 2018 | C5: 8026787 | D5: 12478218 | E5: 16561110 | F5: 19671914 | G5: 23896258 | H5: 27806005 | I5: 33182773 | J5: 36270491 | K5: 37629155 | L5: 40293411 | M5: 41332746 | N5: 43695091 | O5: 44033840 | P5: 45247872 | Q5: 46619184 | R5: 47705616 | S5: 48088887 | T5: 48548192 | U5: 49027700 | V5: 49404837 | W5: 49751067 | X5: 50026159 | Y5: 50392506 | Z5: 50579274 | AB5: 74520233 | AC5: 73564016
A6: AO03 | B6: Q2 2018 | C6: 7547459 | D6: 13305190 | E6: 16410123 | F6: 19898245 | G6: 24703335 | H6: 29063602 | I6: 33129961 | J6: 36336823 | K6: 38481672 | L6: 40628864 | M6: 42718987 | N6: 44050445 | O6: 45153748 | P6: 45915529 | Q6: 46926085 | R6: 48363556 | S6: 48946892 | T6: 49209093 | U6: 49862927 | V6: 50284216 | W6: 50428976 | X6: 50771759 | Y6: 51107802 | AB6: 75524406 | AC6: 74286643
A7: AO04 | B7: Q3 2018 | C7: 8196316 | D7: 14072883 | E7: 15565617 | F7: 20952216 | G7: 24749531 | H7: 28724252 | I7: 33121092 | J7: 36239250 | K7: 39042314 | L7: 41187384 | M7: 43489183 | N7: 44630626 | O7: 45574135 | P7: 46694631 | Q7: 48052882 | R7: 48915394 | S7: 49268124 | T7: 49963443 | U7: 50411848 | V7: 51033429 | W7: 51102720 | X7: 51395178 | AB7: 76542111 | AC7: 76777775
A8: AO05 | B8: Q4 2018 | C8: 8189220 | D8: 12850472 | E8: 17199059 | F8: 20932964 | G8: 25037960 | H8: 29146772 | I8: 32754663 | J8: 37542026 | K8: 39509804 | L8: 41243551 | M8: 43435080 | N8: 45553651 | O8: 47018570 | P8: 47506350 | Q8: 48543727 | R8: 49490339 | S8: 49680980 | T8: 50551414 | U8: 51086096 | V8: 51900283 | W8: 52457834 | AB8: 77573529 | AC8: 78595028
A9: AO06 | B9: Q1 2019 | C9: 8533077 | D9: 13680302 | E9: 16690403 | F9: 21697562 | G9: 25794797 | H9: 30117551 | I9: 33470325 | J9: 39031531 | K9: 39534504 | L9: 42405783 | M9: 44954118 | N9: 45675532 | O9: 46885671 | P9: 48125981 | Q9: 49014808 | R9: 49846037 | S9: 50714853 | T9: 51067131 | U9: 51832054 | V9: 52189573 | AB9: 78618846 | AC9: 78256129
A10: AO07 | B10: Q2 2019 | C10: 9090871 | D10: 13511905 | E10: 17345041 | F10: 21806021 | G10: 25028889 | H10: 30200086 | I10: 35166411 | J10: 37925306 | K10: 40840433 | L10: 42831737 | M10: 44990674 | N10: 46203474 | O10: 47281109 | P10: 48891844 | Q10: 49870444 | R10: 50902793 | S10: 51450099 | T10: 51817100 | U10: 52496431 | AB10: 79678248 | AC10: 81976635
A11: AO08 | B11: Q3 2019 | C11: 8761626 | D11: 13726504 | E11: 18756182 | F11: 21909222 | G11: 25388197 | H11: 30856195 | I11: 34341954 | J11: 39746500 | K11: 41879308 | L11: 42925218 | M11: 45670877 | N11: 47423287 | O11: 48601882 | P11: 49939887 | Q11: 50408360 | R11: 51370763 | S11: 51910061 | T11: 52493077 | AB11: 80751927 | AC11: 81647448
A12: AO09 | B12: Q4 2019 | C12: 8749177 | D12: 14426300 | E12: 18134563 | F12: 22405469 | G12: 26419623 | H12: 31746466 | I12: 35208936 | J12: 41386939 | K12: 42171998 | L12: 43487191 | M12: 45453496 | N12: 48088062 | O12: 48917465 | P12: 50273293 | Q12: 51267767 | R12: 52212664 | S12: 52617714 | AB12: 81840073 | AC12: 81746441
A13: AO10 | B13: Q1 2020 | C13: 8371517 | D13: 14229540 | E13: 18697376 | F13: 22355074 | G13: 26045884 | H13: 31405240 | I13: 36062571 | J13: 39881124 | K13: 42497948 | L13: 44493523 | M13: 46036365 | N13: 48689399 | O13: 49834379 | P13: 51057856 | Q13: 52106577 | R13: 52625937 | AB13: 82942882 | AC13: 82405997
A14: AO11 | B14: Q2 2020 | C14: 8682427 | D14: 14906686 | E14: 18757916 | F14: 22830889 | G14: 29522980 | H14: 32068510 | I14: 36997185 | J14: 41471804 | K14: 43329632 | L14: 43726919 | M14: 47455481 | N14: 48918769 | O14: 50240254 | P14: 51286052 | Q14: 52557910 | AB14: 84060552 | AC14: 83269600
A15: AO12 | B15: Q3 2020 | C15: 10022030 | D15: 13917909 | E15: 19108092 | F15: 21916301 | G15: 27210886 | H15: 32820335 | I15: 36848132 | J15: 40852155 | K15: 43196364 | L15: 43896309 | M15: 47459873 | N15: 49956170 | O15: 51012409 | P15: 51927991 | AB15: 85193283 | AC15: 86364093
A16: AO13 | B16: Q4 2020 | C16: 10087956 | D16: 15373929 | E16: 17870492 | F16: 23254623 | G16: 27462859 | H16: 33114279 | I16: 36827916 | J16: 41964520 | K16: 44426818 | L16: 44996620 | M16: 47898086 | N16: 50415504 | O16: 51522184 | AB16: 86341277 | AC16: 86023052
A17: AO14 | B17: Q1 2021 | C17: 9141610 | D17: 16200065 | E17: 19463623 | F17: 22713844 | G17: 28815023 | H17: 34375385 | I17: 38448539 | J17: 41701968 | K17: 44492052 | L17: 45252217 | M17: 48757427 | N17: 51401276 | AB17: 87504741 | AC17: 85192925
A18: AO15 | B18: Q2 2021 | C18: 9809392 | D18: 14964880 | E18: =19456240+10000000 -> 29456240 | F18: 21886059 | G18: 27984336 | H18: 33309956 | I18: 37548097 | J18: 44170211 | K18: 44580640 | L18: 45267490 | M18: 49785597 | AB18: 88683883 | AC18: 88141373
A19: AO16 | B19: Q3 2021 | C19: 10210239 | D19: 14903106 | E19: 20445946 | F19: 24098871 | G19: 28388139 | H19: 34217767 | I19: 38960082 | J19: 43388072 | K19: 46005265 | L19: 46502204 | AB19: 89878913 | AC19: 91162359
A20: AO17 | B20: Q4 2021 | C20: 9812587 | D20: 15038280 | E20: 20982739 | F20: 23658407 | G20: 30806585 | H20: 33132506 | I20: 39260427 | J20: 44710406 | K20: 46743977 | AB20: 91090047 | AC20: 89354737
A21: AO18 | B21: Q1 2022 | C21: 9656222 | D21: 15173530 | E21: 19994922 | F21: 24377061 | G21: 30354330 | H21: 35076444 | I21: 39440849 | J21: 45510753 | AB21: 92317502 | AC21: 90519813
A22: AO19 | B22: Q2 2022 | C22: 10157249 | D22: 15227277 | E22: 20949821 | F22: 24555011 | G22: 29825871 | H22: 35812219 | I22: 40828576 | AB22: 93561496 | AC22: 93738616
A23: AO20 | B23: Q3 2022 | C23: 10159861 | D23: 14850703 | E23: 21643786 | F23: 25037048 | G23: 30971544 | H23: 35649464 | AB23: 94822254 | AC23: 95003331
A24: AO21 | B24: Q4 2022 | C24: 10216038 | D24: 15551970 | E24: 21643436 | F24: 26300255 | G24: 31915838 | AB24: 96100000 | AC24: 96874956
A25: AO22 | B25: Q1 2023 | C25: 10453025 | D25: 15565827 | E25: 21209178 | F25: 26324052 | AB25: 97394964 | AC25: 99436938
A26: AO23 | B26: Q2 2023 | C26: 10530025 | D26: 16254730 | E26: 22079496 | AB26: 98707378 | AC26: 100036702
A27: AO24 | B27: Q3 2023 | C27: 10382200 | D27: 17132382 | AB27: 100037478 | AC27: 100703868
A28: AO25 | B28: Q4 2023 | C28: 10443357 | AB28: 101385500 | AC28: 102738652
D32: =RANDBETWEEN(-2000000,-500000) -> -802939
D33: =RANDBETWEEN(-2000000,-500000) -> -593402
D34: =RANDBETWEEN(-2000000,-500000) -> -1733191
D35: =RANDBETWEEN(-2000000,-500000) -> -1447820
D36: =RANDBETWEEN(-2000000,-500000) -> -1875249
D37: =RANDBETWEEN(-2000000,-500000) -> -1570295
D38: =RANDBETWEEN(-2000000,-500000) -> -790869
D39: =RANDBETWEEN(-2000000,-500000) -> -892105

Sheet 2_Factores
A1: TRIÁNGULO DE FACTORES DE DESARROLLO · fᵢⱼ = C_{i,j+1}/C_{i,j}
A2: Factores vinculados a 1_Triangulo · Promedio ponderado f̂_j = ΣNum/ΣDen · Factor acumulado y % desarrollado automáticos
A3: AO | B3: Trim. | C3: T01→02 | D3: T02→03 | E3: T03→04 | F3: T04→05 | G3: T05→06 | H3: T06→07 | I3: T07→08 | J3: T08→09 | K3: T09→10 | L3: T10→11 | M3: T11→12 | N3: T12→13 | O3: T13→14 | P3: T14→15 | Q3: T15→16 | R3: T16→17 | S3: T17→18 | T3: T18→19 | U3: T19→20 | V3: T20→21 | W3: T21→22 | X3: T22→23 | Y3: T23→24 | Z3: T24→25
A4: AO01 | B4: Q4 2017 | C4: ='1_Triangulo'!D4/'1_Triangulo'!C4 -> 1.5850805 | D4: ='1_Triangulo'!E4/'1_Triangulo'!D4 -> 1.2920963 | E4: ='1_Triangulo'!F4/'1_Triangulo'!E4 -> 1.2438847 | F4: ='1_Triangulo'!G4/'1_Triangulo'!F4 -> 1.1521487 | G4: ='1_Triangulo'!H4/'1_Triangulo'!G4 -> 1.1702438 | H4: ='1_Triangulo'!I4/'1_Triangulo'!H4 -> 1.1798567 | I4: ='1_Triangulo'!J4/'1_Triangulo'!I4 -> 1.1099839 | J4: ='1_Triangulo'!K4/'1_Triangulo'!J4 -> 1.0334787 | ... Z4: ='1_Triangulo'!AA4/'1_Triangulo'!Z4 -> 1.003523
A5: AO02 | B5: Q1 2018 | C5: ='1_Triangulo'!D5/'1_Triangulo'!C5 -> 1.554572 | D5: ='1_Triangulo'!E5/'1_Triangulo'!D5 -> 1.3272015 | E5: ='1_Triangulo'!F5/'1_Triangulo'!E5 -> 1.1878379 | F5: ='1_Triangulo'!G5/'1_Triangulo'!F5 -> 1.2147399 | G5: ='1_Triangulo'!H5/'1_Triangulo'!G5 -> 1.1636134 | H5: ='1_Triangulo'!I5/'1_Triangulo'!H5 -> 1.1933672 | I5: ='1_Triangulo'!J5/'1_Triangulo'!I5 -> 1.0930518 | J5: ='1_Triangulo'!K5/'1_Triangulo'!J5 -> 1.0374592 | ... Y5: ='1_Triangulo'!Z5/'1_Triangulo'!Y5 -> 1.0037063
A6: AO03 | B6: Q2 2018 | C6: ='1_Triangulo'!D6/'1_Triangulo'!C6 -> 1.7628701 | D6: ='1_Triangulo'!E6/'1_Triangulo'!D6 -> 1.2333625 | E6: ='1_Triangulo'!F6/'1_Triangulo'!E6 -> 1.2125592 | F6: ='1_Triangulo'!G6/'1_Triangulo'!F6 -> 1.2414831 | G6: ='1_Triangulo'!H6/'1_Triangulo'!G6 -> 1.1765052 | H6: ='1_Triangulo'!I6/'1_Triangulo'!H6 -> 1.1399124 | I6: ='1_Triangulo'!J6/'1_Triangulo'!I6 -> 1.0967964 | J6: ='1_Triangulo'!K6/'1_Triangulo'!J6 -> 1.0590269 | ... X6: ='1_Triangulo'!Y6/'1_Triangulo'!X6 -> 1.0066187
A7: AO04 | B7: Q3 2018 | C7: ='1_Triangulo'!D7/'1_Triangulo'!C7 -> 1.7169766 | D7: ='1_Triangulo'!E7/'1_Triangulo'!D7 -> 1.1060717 | E7: ='1_Triangulo'!F7/'1_Triangulo'!E7 -> 1.3460575 | F7: ='1_Triangulo'!G7/'1_Triangulo'!F7 -> 1.1812369 | G7: ='1_Triangulo'!H7/'1_Triangulo'!G7 -> 1.1605978 | H7: ='1_Triangulo'!I7/'1_Triangulo'!H7 -> 1.1530707 | I7: ='1_Triangulo'!J7/'1_Triangulo'!I7 -> 1.0941442 | J7: ='1_Triangulo'!K7/'1_Triangulo'!J7 -> 1.0773488 | ... W7: ='1_Triangulo'!X7/'1_Triangulo'!W7 -> 1.0057229
A8: AO05 | B8: Q4 2018 | C8: ='1_Triangulo'!D8/'1_Triangulo'!C8 -> 1.5691936 | D8: ='1_Triangulo'!E8/'1_Triangulo'!D8 -> 1.338399 | E8: ='1_Triangulo'!F8/'1_Triangulo'!E8 -> 1.2170994 | F8: ='1_Triangulo'!G8/'1_Triangulo'!F8 -> 1.196102 | G8: ='1_Triangulo'!H8/'1_Triangulo'!G8 -> 1.1641033 | H8: ='1_Triangulo'!I8/'1_Triangulo'!H8 -> 1.1237836 | I8: ='1_Triangulo'!J8/'1_Triangulo'!I8 -> 1.1461582 | J8: ='1_Triangulo'!K8/'1_Triangulo'!J8 -> 1.0524153 | ... V8: ='1_Triangulo'!W8/'1_Triangulo'!V8 -> 1.0107427
A9: AO06 | B9: Q1 2019 | C9: ='1_Triangulo'!D9/'1_Triangulo'!C9 -> 1.6032085 | D9: ='1_Triangulo'!E9/'1_Triangulo'!D9 -> 1.2200318 | E9: ='1_Triangulo'!F9/'1_Triangulo'!E9 -> 1.3000023 | F9: ='1_Triangulo'!G9/'1_Triangulo'!F9 -> 1.1888339 | G9: ='1_Triangulo'!H9/'1_Triangulo'!G9 -> 1.1675824 | H9: ='1_Triangulo'!I9/'1_Triangulo'!H9 -> 1.1113229 | I9: ='1_Triangulo'!J9/'1_Triangulo'!I9 -> 1.1661533 | J9: ='1_Triangulo'!K9/'1_Triangulo'!J9 -> 1.0128863 | ... U9: ='1_Triangulo'!V9/'1_Triangulo'!U9 -> 1.0068976
A10: AO07 | B10: Q2 2019 | C10: ='1_Triangulo'!D10/'1_Triangulo'!C10 -> 1.4863158 | D10: ='1_Triangulo'!E10/'1_Triangulo'!D10 -> 1.2836858 | E10: ='1_Triangulo'!F10/'1_Triangulo'!E10 -> 1.2571905 | F10: ='1_Triangulo'!G10/'1_Triangulo'!F10 -> 1.1477972 | G10: ='1_Triangulo'!H10/'1_Triangulo'!G10 -> 1.2066091 | H10: ='1_Triangulo'!I10/'1_Triangulo'!H10 -> 1.1644474 | I10: ='1_Triangulo'!J10/'1_Triangulo'!I10 -> 1.0784526 | J10: ='1_Triangulo'!K10/'1_Triangulo'!J10 -> 1.076865 | ... T10: ='1_Triangulo'!U10/'1_Triangulo'!T10 -> 1.0131102
A11: AO08 | B11: Q3 2019 | C11: ='1_Triangulo'!D11/'1_Triangulo'!C11 -> 1.5666617 | D11: ='1_Triangulo'!E11/'1_Triangulo'!D11 -> 1.3664209 | E11: ='1_Triangulo'!F11/'1_Triangulo'!E11 -> 1.1681067 | F11: ='1_Triangulo'!G11/'1_Triangulo'!F11 -> 1.1587904 | G11: ='1_Triangulo'!H11/'1_Triangulo'!G11 -> 1.2153756 | H11: ='1_Triangulo'!I11/'1_Triangulo'!H11 -> 1.1129679 | I11: ='1_Triangulo'!J11/'1_Triangulo'!I11 -> 1.1573744 | J11: ='1_Triangulo'!K11/'1_Triangulo'!J11 -> 1.0536603 | ... S11: ='1_Triangulo'!T11/'1_Triangulo'!S11 -> 1.0112313
A12: AO09 | B12: Q4 2019 | C12: ='1_Triangulo'!D12/'1_Triangulo'!C12 -> 1.6488751 | D12: ='1_Triangulo'!E12/'1_Triangulo'!D12 -> 1.2570488 | E12: ='1_Triangulo'!F12/'1_Triangulo'!E12 -> 1.2355119 | F12: ='1_Triangulo'!G12/'1_Triangulo'!F12 -> 1.1791596 | G12: ='1_Triangulo'!H12/'1_Triangulo'!G12 -> 1.2016245 | H12: ='1_Triangulo'!I12/'1_Triangulo'!H12 -> 1.1090663 | I12: ='1_Triangulo'!J12/'1_Triangulo'!I12 -> 1.1754669 | J12: ='1_Triangulo'!K12/'1_Triangulo'!J12 -> 1.0189688 | ... R12: ='1_Triangulo'!S12/'1_Triangulo'!R12 -> 1.0077577
A13: AO10 | B13: Q1 2020 | C13: ='1_Triangulo'!D13/'1_Triangulo'!C13 -> 1.6997564 | D13: ='1_Triangulo'!E13/'1_Triangulo'!D13 -> 1.3139832 | E13: ='1_Triangulo'!F13/'1_Triangulo'!E13 -> 1.1956263 | F13: ='1_Triangulo'!G13/'1_Triangulo'!F13 -> 1.1650994 | G13: ='1_Triangulo'!H13/'1_Triangulo'!G13 -> 1.2057659 | H13: ='1_Triangulo'!I13/'1_Triangulo'!H13 -> 1.1482979 | I13: ='1_Triangulo'!J13/'1_Triangulo'!I13 -> 1.1058869 | J13: ='1_Triangulo'!K13/'1_Triangulo'!J13 -> 1.0656156 | ... Q13: ='1_Triangulo'!R13/'1_Triangulo'!Q13 -> 1.0099673
A14: AO11 | B14: Q2 2020 | C14: ='1_Triangulo'!D14/'1_Triangulo'!C14 -> 1.7168801 | D14: ='1_Triangulo'!E14/'1_Triangulo'!D14 -> 1.2583559 | E14: ='1_Triangulo'!F14/'1_Triangulo'!E14 -> 1.2171336 | F14: ='1_Triangulo'!G14/'1_Triangulo'!F14 -> 1.2931157 | G14: ='1_Triangulo'!H14/'1_Triangulo'!G14 -> 1.086222 | H14: ='1_Triangulo'!I14/'1_Triangulo'!H14 -> 1.153692 | I14: ='1_Triangulo'!J14/'1_Triangulo'!I14 -> 1.1209449 | J14: ='1_Triangulo'!K14/'1_Triangulo'!J14 -> 1.0447974 | ... P14: ='1_Triangulo'!Q14/'1_Triangulo'!P14 -> 1.0247993
A15: AO12 | B15: Q3 2020 | C15: ='1_Triangulo'!D15/'1_Triangulo'!C15 -> 1.3887315 | D15: ='1_Triangulo'!E15/'1_Triangulo'!D15 -> 1.372914 | E15: ='1_Triangulo'!F15/'1_Triangulo'!E15 -> 1.1469644 | F15: ='1_Triangulo'!G15/'1_Triangulo'!F15 -> 1.2415821 | G15: ='1_Triangulo'!H15/'1_Triangulo'!G15 -> 1.2061472 | H15: ='1_Triangulo'!I15/'1_Triangulo'!H15 -> 1.1227226 | I15: ='1_Triangulo'!J15/'1_Triangulo'!I15 -> 1.1086628 | J15: ='1_Triangulo'!K15/'1_Triangulo'!J15 -> 1.0573828 | ... O15: ='1_Triangulo'!P15/'1_Triangulo'!O15 -> 1.0179482
A16: AO13 | B16: Q4 2020 | C16: ='1_Triangulo'!D16/'1_Triangulo'!C16 -> 1.5239885 | D16: ='1_Triangulo'!E16/'1_Triangulo'!D16 -> 1.1623894 | E16: ='1_Triangulo'!F16/'1_Triangulo'!E16 -> 1.3012861 | F16: ='1_Triangulo'!G16/'1_Triangulo'!F16 -> 1.1809634 | G16: ='1_Triangulo'!H16/'1_Triangulo'!G16 -> 1.2057841 | H16: ='1_Triangulo'!I16/'1_Triangulo'!H16 -> 1.1121461 | I16: ='1_Triangulo'!J16/'1_Triangulo'!I16 -> 1.1394758 | J16: ='1_Triangulo'!K16/'1_Triangulo'!J16 -> 1.0586757 | ... N16: ='1_Triangulo'!O16/'1_Triangulo'!N16 -> 1.0219512
A17: AO14 | B17: Q1 2021 | C17: ='1_Triangulo'!D17/'1_Triangulo'!C17 -> 1.7721238 | D17: ='1_Triangulo'!E17/'1_Triangulo'!D17 -> 1.2014534 | E17: ='1_Triangulo'!F17/'1_Triangulo'!E17 -> 1.1669895 | F17: ='1_Triangulo'!G17/'1_Triangulo'!F17 -> 1.2686106 | G17: ='1_Triangulo'!H17/'1_Triangulo'!G17 -> 1.1929675 | H17: ='1_Triangulo'!I17/'1_Triangulo'!H17 -> 1.1184904 | I17: ='1_Triangulo'!J17/'1_Triangulo'!I17 -> 1.0846178 | J17: ='1_Triangulo'!K17/'1_Triangulo'!J17 -> 1.0669053 | ... M17: ='1_Triangulo'!N17/'1_Triangulo'!M17 -> 1.0542245
A18: AO15 | B18: Q2 2021 | C18: ='1_Triangulo'!D18/'1_Triangulo'!C18 -> 1.5255665 | D18: ='1_Triangulo'!E18/'1_Triangulo'!D18 -> 1.9683579 | E18: ='1_Triangulo'!F18/'1_Triangulo'!E18 -> 0.74300247 | F18: ='1_Triangulo'!G18/'1_Triangulo'!F18 -> 1.2786375 | G18: ='1_Triangulo'!H18/'1_Triangulo'!G18 -> 1.1903072 | H18: ='1_Triangulo'!I18/'1_Triangulo'!H18 -> 1.1272335 | I18: ='1_Triangulo'!J18/'1_Triangulo'!I18 -> 1.1763635 | J18: ='1_Triangulo'!K18/'1_Triangulo'!J18 -> 1.009292 | ... L18: ='1_Triangulo'!M18/'1_Triangulo'!L18 -> 1.0998091
A19: AO16 | B19: Q3 2021 | C19: ='1_Triangulo'!D19/'1_Triangulo'!C19 -> 1.4596236 | D19: ='1_Triangulo'!E19/'1_Triangulo'!D19 -> 1.3719252 | E19: ='1_Triangulo'!F19/'1_Triangulo'!E19 -> 1.1786626 | F19: ='1_Triangulo'!G19/'1_Triangulo'!F19 -> 1.1779863 | G19: ='1_Triangulo'!H19/'1_Triangulo'!G19 -> 1.2053544 | H19: ='1_Triangulo'!I19/'1_Triangulo'!H19 -> 1.1385922 | I19: ='1_Triangulo'!J19/'1_Triangulo'!I19 -> 1.1136545 | J19: ='1_Triangulo'!K19/'1_Triangulo'!J19 -> 1.0603206 | K19: ='1_Triangulo'!L19/'1_Triangulo'!K19 -> 1.0108018
A20: AO17 | B20: Q4 2021 | C20: ='1_Triangulo'!D20/'1_Triangulo'!C20 -> 1.53255 | D20: ='1_Triangulo'!E20/'1_Triangulo'!D20 -> 1.3952885 | E20: ='1_Triangulo'!F20/'1_Triangulo'!E20 -> 1.1275176 | F20: ='1_Triangulo'!G20/'1_Triangulo'!F20 -> 1.3021411 | G20: ='1_Triangulo'!H20/'1_Triangulo'!G20 -> 1.0755008 | H20: ='1_Triangulo'!I20/'1_Triangulo'!H20 -> 1.1849519 | I20: ='1_Triangulo'!J20/'1_Triangulo'!I20 -> 1.1388161 | J20: ='1_Triangulo'!K20/'1_Triangulo'!J20 -> 1.0454832
A21: AO18 | B21: Q1 2022 | C21: ='1_Triangulo'!D21/'1_Triangulo'!C21 -> 1.5713734 | D21: ='1_Triangulo'!E21/'1_Triangulo'!D21 -> 1.3177502 | E21: ='1_Triangulo'!F21/'1_Triangulo'!E21 -> 1.2191626 | F21: ='1_Triangulo'!G21/'1_Triangulo'!F21 -> 1.2452006 | G21: ='1_Triangulo'!H21/'1_Triangulo'!G21 -> 1.1555664 | H21: ='1_Triangulo'!I21/'1_Triangulo'!H21 -> 1.1244255 | I21: ='1_Triangulo'!J21/'1_Triangulo'!I21 -> 1.1538989
A22: AO19 | B22: Q2 2022 | C22: ='1_Triangulo'!D22/'1_Triangulo'!C22 -> 1.4991537 | D22: ='1_Triangulo'!E22/'1_Triangulo'!D22 -> 1.3758088 | E22: ='1_Triangulo'!F22/'1_Triangulo'!E22 -> 1.1720869 | F22: ='1_Triangulo'!G22/'1_Triangulo'!F22 -> 1.2146552 | G22: ='1_Triangulo'!H22/'1_Triangulo'!G22 -> 1.2007099 | H22: ='1_Triangulo'!I22/'1_Triangulo'!H22 -> 1.1400739
A23: AO20 | B23: Q3 2022 | C23: ='1_Triangulo'!D23/'1_Triangulo'!C23 -> 1.4617034 | D23: ='1_Triangulo'!E23/'1_Triangulo'!D23 -> 1.457425 | E23: ='1_Triangulo'!F23/'1_Triangulo'!E23 -> 1.1567777 | F23: ='1_Triangulo'!G23/'1_Triangulo'!F23 -> 1.2370286 | G23: ='1_Triangulo'!H23/'1_Triangulo'!G23 -> 1.1510393
A24: AO21 | B24: Q4 2022 | C24: ='1_Triangulo'!D24/'1_Triangulo'!C24 -> 1.5223093 | D24: ='1_Triangulo'!E24/'1_Triangulo'!D24 -> 1.3916845 | E24: ='1_Triangulo'!F24/'1_Triangulo'!E24 -> 1.2151608 | F24: ='1_Triangulo'!G24/'1_Triangulo'!F24 -> 1.2135182
A25: AO22 | B25: Q1 2023 | C25: ='1_Triangulo'!D25/'1_Triangulo'!C25 -> 1.4891218 | D25: ='1_Triangulo'!E25/'1_Triangulo'!D25 -> 1.3625475 | E25: ='1_Triangulo'!F25/'1_Triangulo'!E25 -> 1.2411632
A26: AO23 | B26: Q2 2023 | C26: ='1_Triangulo'!D26/'1_Triangulo'!C26 -> 1.5436554 | D26: ='1_Triangulo'!E26/'1_Triangulo'!D26 -> 1.3583428
A27: AO24 | B27: Q3 2023 | C27: ='1_Triangulo'!D27/'1_Triangulo'!C27 -> 1.6501688
A28: AO25 | B28: Q4 2023
A29: Σ Numerador (C_{j+1}) | C29: =SUM('1_Triangulo'!D4:D27) -> 350091755 | D29: =SUM('1_Triangulo'!E4:E26)-'1_Triangulo'!E18 -> 415982072 | E29: =SUM('1_Triangulo'!F4:F25)-'1_Triangulo'!F18 -> 477185750 | F29: =SUM('1_Triangulo'!G4:G24) -> 573931200 | G29: =SUM('1_Triangulo'!H4:H23) -> 636270541 | H29: =SUM('1_Triangulo'!I4:I22) -> 684194987 | I29: =SUM('1_Triangulo'!J4:J21) -> 724311468 | J29: =SUM('1_Triangulo'!K4:K20) -> 711754786 | K29: =SUM('1_Triangulo'!L14:L19) -> 2.6964176e+08 | L29: =SUM('1_Triangulo'!M4:M18) -> 680497811 | M29: =SUM('1_Triangulo'!N4:N17) -> 657592558 | N29: =SUM('1_Triangulo'!O4:O16) -> 620161119 | O29: =SUM('1_Triangulo'!P4:P15) -> 581365128 | P29: =SUM('1_Triangulo'!Q4:Q14) -> 540936102 | Q29: =SUM('1_Triangulo'!R4:R13) -> 498246991 | R29: =SUM('1_Triangulo'!S4:S12) -> 449923648 | S29: =SUM('1_Triangulo'!T4:T11) -> 401616506 | T29: =SUM('1_Triangulo'!U4:U10) -> 353014021 | U29: =SUM('1_Triangulo'!V4:V9) -> 303567757 | V29: =SUM('1_Triangulo'!W4:W8) -> 253044296 | W29: =SUM('1_Triangulo'!X4:X7) -> 201573982 | X29: =SUM('1_Triangulo'!Y4:Y6) -> 151150254 | Y29: =SUM('1_Triangulo'!Z4:Z5) -> 100374105 | Z29: =SUM('1_Triangulo'!AA4:AA4) -> 49970260
A30: Σ Denominador (C_j) | C30: =SUM('1_Triangulo'!C4:C27) -> 222830141 | D30: =SUM('1_Triangulo'!D4:D26)-'1_Triangulo'!D18 -> 317994493 | E30: =SUM('1_Triangulo'!E4:E25)-'1_Triangulo'!E18 -> 393902576 | F30: =SUM('1_Triangulo'!F4:F24) -> 472747757 | G30: =SUM('1_Triangulo'!G4:G23) -> 542015362 | H30: =SUM('1_Triangulo'!H4:H22) -> 600621077 | I30: =SUM('1_Triangulo'!I4:I21) -> 643366411 | J30: =SUM('1_Triangulo'!J4:J20) -> 678800715 | K30: =SUM('1_Triangulo'!K14:K19) -> 266030771 | L30: =SUM('1_Triangulo'!L4:L18) -> 6.4227862e+08 | M30: =SUM('1_Triangulo'!M4:M17) -> 630712214 | N30: =SUM('1_Triangulo'!N4:N16) -> 606191282 | O30: =SUM('1_Triangulo'!O4:O15) -> 568638935 | P30: =SUM('1_Triangulo'!P4:P14) -> 529437137 | Q30: =SUM('1_Triangulo'!Q4:Q13) -> 488378192 | R30: =SUM('1_Triangulo'!R4:R12) -> 445621054 | S30: =SUM('1_Triangulo'!S4:S11) -> 397305934 | T30: =SUM('1_Triangulo'!T4:T10) -> 349123429 | U30: =SUM('1_Triangulo'!U4:U9) -> 300517590 | V30: =SUM('1_Triangulo'!V4:V8) -> 251378184 | W30: =SUM('1_Triangulo'!W4:W7) -> 200586462 | X30: =SUM('1_Triangulo'!X4:X6) -> 150178804 | Y30: =SUM('1_Triangulo'!Y4:Y5) -> 100042452 | Z30: =SUM('1_Triangulo'!Z4:Z4) -> 49794831
A31: Factor f̂_j (pond.) | C31: =C29/C30 -> 1.5711149 | D31: =D29/D30 -> 1.3081424 | E31: =E29/E30 -> 1.2114309 | F31: =F29/F30 -> 1.2140326 | G31: =G29/G30 -> 1.1738976 | H31: =H29/H30 -> 1.1391458 | I31: =I29/I30 -> 1.1258149 | J31: =J29/J30 -> 1.0485475 | ... Z31: =Z29/Z30 -> 1.003523
A33: Factor acum. F_j^{→25} | C33: =C31*D33 -> 6.224337 | D33: =D31*E33 -> 3.9617325 | E33: =E31*F33 -> 3.0285178 | F33: =F31*G33 -> 2.4999509 | G33: =G31*H33 -> 2.0592123 | H33: =H31*I33 -> 1.7541669 | I33: =I31*J33 -> 1.5398967 | J33: =J31*K33 -> 1.3678063 | ... Y33: =Y31*Z33 -> 1.0068498 | Z33: =Z31 -> 1.003523
A34: % Desarrollado = 1/F_j | C34: =1/C33 -> 0.16065968 | D34: =1/D33 -> 0.25241482 | E34: =1/E33 -> 0.33019452 | F34: =1/F33 -> 0.40000785 | G34: =1/G33 -> 0.48562258 | H34: =1/H33 -> 0.57007119 | I34: =1/I33 -> 0.64939421 | J34: =1/J33 -> 0.73109765 | ... Z34: =1/Z33 -> 0.99648933
A35: % No-Des. = 1−%Des | C35: =1-C34 -> 0.83934032 | D35: =1-D34 -> 0.74758518 | E35: =1-E34 -> 0.66980548 | F35: =1-F34 -> 0.59999215 | G35: =1-G34 -> 0.51437742 | H35: =1-H34 -> 0.42992881 | I35: =1-I34 -> 0.35060579 | J35: =1-J34 -> 0.26890235 | ... Z35: =1-Z34 -> 0.0035106681

Sheet 3_ChainLadder
A1: CHAIN-LADDER — Triángulo Proyectado e IBNR | Vinculado a hojas 1_Triangulo y 2_Factores
A2: AZUL=observado (hoja 1) · AMARILLO=proyección CL = C_{i,j-1} × f̂_{j-1} (hoja 2) · VERDE=IBNR
A3: AO | B3: Trim. | C3: T01 | D3: T02 | E3: T03 | F3: T04 | G3: T05 | H3: T06 | I3: T07 | J3: T08 | K3: T09 | L3: T10 | M3: T11 | N3: T12 | O3: T13 | P3: T14 | Q3: T15 | R3: T16 | S3: T17 | T3: T18 | U3: T19 | V3: T20 | W3: T21 | X3: T22 | Y3: T23 | Z3: T24 | AA3: T25 | AB3: Último Proy. | AC3: Pagado Actual | AD3: IBNR CL
A4: AO01 | B4: Q4 2017 | C4: ='1_Triangulo'!C4 -> 8043230 | D4: ='1_Triangulo'!D4 -> 12749167 | E4: ='1_Triangulo'!E4 -> 16473151 | F4: ='1_Triangulo'!F4 -> 20490701 | G4: ='1_Triangulo'!G4 -> 23608335 | H4: ='1_Triangulo'!H4 -> 27627507 | I4: ='1_Triangulo'!I4 -> 32596498 | J4: ='1_Triangulo'!J4 -> 36181589 | ... AA4: ='1_Triangulo'!AA4 -> 49970260 | AB4: =AA4 -> 49970260 | AC4: ='1_Triangulo'!AA4 -> 49970260 | AD4: =AB4-AC4 -> 0
A5: AO02 | B5: Q1 2018 | C5: ='1_Triangulo'!C5 -> 8026787 | D5: ='1_Triangulo'!D5 -> 12478218 | E5: ='1_Triangulo'!E5 -> 16561110 | F5: ='1_Triangulo'!F5 -> 19671914 | G5: ='1_Triangulo'!G5 -> 23896258 | H5: ='1_Triangulo'!H5 -> 27806005 | I5: ='1_Triangulo'!I5 -> 33182773 | J5: ='1_Triangulo'!J5 -> 36270491 | ... Z5: ='1_Triangulo'!Z5 -> 50579274 | AA5: =Z5*'2_Factores'!Z31 -> 50757467 | AB5: =AA5 -> 50757467 | AC5: ='1_Triangulo'!Z5 -> 50579274 | AD5: =AB5-AC5 -> 178192.62
A6: AO03 | B6: Q2 2018 | C6: ='1_Triangulo'!C6 -> 7547459 | D6: ='1_Triangulo'!D6 -> 13305190 | E6: ='1_Triangulo'!E6 -> 16410123 | F6: ='1_Triangulo'!F6 -> 19898245 | G6: ='1_Triangulo'!G6 -> 24703335 | H6: ='1_Triangulo'!H6 -> 29063602 | I6: ='1_Triangulo'!I6 -> 33129961 | J6: ='1_Triangulo'!J6 -> 36336823 | ... Y6: ='1_Triangulo'!Y6 -> 51107802 | Z6: =Y6*'2_Factores'!Y31 -> 51277231 | AA6: =Z6*'2_Factores'!Z31 -> 51457882 | AB6: =AA6 -> 51457882 | AC6: ='1_Triangulo'!Y6 -> 51107802 | AD6: =AB6-AC6 -> 350080.18
A7: AO04 | B7: Q3 2018 | C7: ='1_Triangulo'!C7 -> 8196316 | D7: ='1_Triangulo'!D7 -> 14072883 | E7: ='1_Triangulo'!E7 -> 15565617 | F7: ='1_Triangulo'!F7 -> 20952216 | G7: ='1_Triangulo'!G7 -> 24749531 | H7: ='1_Triangulo'!H7 -> 28724252 | I7: ='1_Triangulo'!I7 -> 33121092 | J7: ='1_Triangulo'!J7 -> 36239250 | ... X7: ='1_Triangulo'!X7 -> 51395178 | Y7: =X7*'2_Factores'!X31 -> 51727634 | Z7: =Y7*'2_Factores'!Y31 -> 51899117 | AA7: =Z7*'2_Factores'!Z31 -> 52081960 | AB7: =AA7 -> 52081960 | AC7: ='1_Triangulo'!X7 -> 51395178 | AD7: =AB7-AC7 -> 686781.94
A8: AO05 | B8: Q4 2018 | C8: ='1_Triangulo'!C8 -> 8189220 | D8: ='1_Triangulo'!D8 -> 12850472 | E8: ='1_Triangulo'!E8 -> 17199059 | F8: ='1_Triangulo'!F8 -> 20932964 | G8: ='1_Triangulo'!G8 -> 25037960 | H8: ='1_Triangulo'!H8 -> 29146772 | I8: ='1_Triangulo'!I8 -> 32754663 | J8: ='1_Triangulo'!J8 -> 37542026 | ... W8: ='1_Triangulo'!W8 -> 52457834 | X8: =W8*'2_Factores'!W31 -> 52716093 | Y8: =X8*'2_Factores'!X31 -> 53057093 | Z8: =Y8*'2_Factores'!Y31 -> 53232984 | AA8: =Z8*'2_Factores'!Z31 -> 53420526 | AB8: =AA8 -> 53420526 | AC8: ='1_Triangulo'!W8 -> 52457834 | AD8: =AB8-AC8 -> 962691.52
A9: AO06 | B9: Q1 2019 | C9: ='1_Triangulo'!C9 -> 8533077 | D9: ='1_Triangulo'!D9 -> 13680302 | E9: ='1_Triangulo'!E9 -> 16690403 | F9: ='1_Triangulo'!F9 -> 21697562 | G9: ='1_Triangulo'!G9 -> 25794797 | H9: ='1_Triangulo'!H9 -> 30117551 | I9: ='1_Triangulo'!I9 -> 33470325 | J9: ='1_Triangulo'!J9 -> 39031531 | ... V9: ='1_Triangulo'!V9 -> 52189573 | W9: =V9*'2_Factores'!V31 -> 52535481 | X9: =W9*'2_Factores'!W31 -> 52794122 | Y9: =X9*'2_Factores'!X31 -> 53135627 | Z9: =Y9*'2_Factores'!Y31 -> 53311778 | AA9: =Z9*'2_Factores'!Z31 -> 53499597 | AB9: =AA9 -> 53499597 | AC9: ='1_Triangulo'!V9 -> 52189573 | AD9: =AB9-AC9 -> 1310024.3
A10: AO07 | B10: Q2 2019 | C10: ='1_Triangulo'!C10 -> 9090871 | D10: ='1_Triangulo'!D10 -> 13511905 | E10: ='1_Triangulo'!E10 -> 17345041 | F10: ='1_Triangulo'!F10 -> 21806021 | G10: ='1_Triangulo'!G10 -> 25028889 | H10: ='1_Triangulo'!H10 -> 30200086 | I10: ='1_Triangulo'!I10 -> 35166411 | J10: ='1_Triangulo'!J10 -> 37925306 | ... U10: ='1_Triangulo'!U10 -> 52496431 | V10: =U10*'2_Factores'!U31 -> 53029255 | W10: =V10*'2_Factores'!V31 -> 53380728 | X10: =W10*'2_Factores'!W31 -> 53643530 | Y10: =X10*'2_Factores'!X31 -> 53990530 | Z10: =Y10*'2_Factores'!Y31 -> 54169515 | AA10: =Z10*'2_Factores'!Z31 -> 54360356 | AB10: =AA10 -> 54360356 | AC10: ='1_Triangulo'!U10 -> 52496431 | AD10: =AB10-AC10 -> 1863925
A11: AO08 | B11: Q3 2019 | C11: ='1_Triangulo'!C11 -> 8761626 | D11: ='1_Triangulo'!D11 -> 13726504 | E11: ='1_Triangulo'!E11 -> 18756182 | F11: ='1_Triangulo'!F11 -> 21909222 | G11: ='1_Triangulo'!G11 -> 25388197 | H11: ='1_Triangulo'!H11 -> 30856195 | I11: ='1_Triangulo'!I11 -> 34341954 | J11: ='1_Triangulo'!J11 -> 39746500 | ... T11: ='1_Triangulo'!T11 -> 52493077 | U11: =T11*'2_Factores'!T31 -> 53078054 | V11: =U11*'2_Factores'!U31 -> 53616781 | W11: =V11*'2_Factores'!V31 -> 53972148 | X11: =W11*'2_Factores'!W31 -> 54237862 | Y11: =X11*'2_Factores'!X31 -> 54588706 | Z11: =Y11*'2_Factores'!Y31 -> 54769674 | AA11: =Z11*'2_Factores'!Z31 -> 54962630 | AB11: =AA11 -> 54962630 | AC11: ='1_Triangulo'!T11 -> 52493077 | AD11: =AB11-AC11 -> 2469552.9
A12: AO09 | B12: Q4 2019 | C12: ='1_Triangulo'!C12 -> 8749177 | D12: ='1_Triangulo'!D12 -> 14426300 | E12: ='1_Triangulo'!E12 -> 18134563 | F12: ='1_Triangulo'!F12 -> 22405469 | G12: ='1_Triangulo'!G12 -> 26419623 | H12: ='1_Triangulo'!H12 -> 31746466 | I12: ='1_Triangulo'!I12 -> 35208936 | J12: ='1_Triangulo'!J12 -> 41386939 | ... S12: ='1_Triangulo'!S12 -> 52617714 | T12: =S12*'2_Factores'!S31 -> 53188590 | U12: =T12*'2_Factores'!T31 -> 53781318 | V12: =U12*'2_Factores'!U31 -> 54327183 | W12: =V12*'2_Factores'!V31 -> 54687258 | X12: =W12*'2_Factores'!W31 -> 54956493 | Y12: =X12*'2_Factores'!X31 -> 55311985 | Z12: =Y12*'2_Factores'!Y31 -> 55495351 | AA12: =Z12*'2_Factores'!Z31 -> 55690864 | AB12: =AA12 -> 55690864 | AC12: ='1_Triangulo'!S12 -> 52617714 | AD12: =AB12-AC12 -> 3073149.5
A13: AO10 | B13: Q1 2020 | C13: ='1_Triangulo'!C13 -> 8371517 | D13: ='1_Triangulo'!D13 -> 14229540 | E13: ='1_Triangulo'!E13 -> 18697376 | F13: ='1_Triangulo'!F13 -> 22355074 | G13: ='1_Triangulo'!G13 -> 26045884 | H13: ='1_Triangulo'!H13 -> 31405240 | I13: ='1_Triangulo'!I13 -> 36062571 | J13: ='1_Triangulo'!J13 -> 39881124 | ... R13: ='1_Triangulo'!R13 -> 52625937 | S13: =R13*'2_Factores'!R31 -> 53134055 | T13: =S13*'2_Factores'!S31 -> 53710533 | U13: =T13*'2_Factores'!T31 -> 54309077 | V13: =U13*'2_Factores'!U31 -> 54860299 | W13: =V13*'2_Factores'!V31 -> 55223908 | X13: =W13*'2_Factores'!W31 -> 55495784 | Y13: =X13*'2_Factores'!X31 -> 55854765 | Z13: =Y13*'2_Factores'!Y31 -> 56039931 | AA13: =Z13*'2_Factores'!Z31 -> 56237361 | AB13: =AA13 -> 56237361 | AC13: ='1_Triangulo'!R13 -> 52625937 | AD13: =AB13-AC13 -> 3611424.5
A14: AO11 | B14: Q2 2020 | C14: ='1_Triangulo'!C14 -> 8682427 | D14: ='1_Triangulo'!D14 -> 14906686 | E14: ='1_Triangulo'!E14 -> 18757916 | F14: ='1_Triangulo'!F14 -> 22830889 | G14: ='1_Triangulo'!G14 -> 29522980 | H14: ='1_Triangulo'!H14 -> 32068510 | I14: ='1_Triangulo'!I14 -> 36997185 | J14: ='1_Triangulo'!J14 -> 41471804 | ... Q14: ='1_Triangulo'!Q14 -> 52557910 | R14: =Q14*'2_Factores'!Q31 -> 53619963 | S14: =R14*'2_Factores'!R31 -> 54137678 | T14: =S14*'2_Factores'!S31 -> 54725045 | U14: =T14*'2_Factores'!T31 -> 55334895 | V14: =U14*'2_Factores'!U31 -> 55896528 | W14: =V14*'2_Factores'!V31 -> 56267005 | X14: =W14*'2_Factores'!W31 -> 56544017 | Y14: =X14*'2_Factores'!X31 -> 56909779 | ... AA14: =Z14*'2_Factores'!Z31 -> 57299602 | AB14: =AA14 -> 57299602 | AC14: ='1_Triangulo'!Q14 -> 52557910 | AD14: =AB14-AC14 -> 4741691.8
A15: AO12 | B15: Q3 2020 | C15: ='1_Triangulo'!C15 -> 10022030 | D15: ='1_Triangulo'!D15 -> 13917909 | E15: ='1_Triangulo'!E15 -> 19108092 | F15: ='1_Triangulo'!F15 -> 21916301 | G15: ='1_Triangulo'!G15 -> 27210886 | H15: ='1_Triangulo'!H15 -> 32820335 | I15: ='1_Triangulo'!I15 -> 36848132 | J15: ='1_Triangulo'!J15 -> 40852155 | ... P15: ='1_Triangulo'!P15 -> 51927991 | Q15: =P15*'2_Factores'!P31 -> 53055827 | R15: =Q15*'2_Factores'!Q31 -> 54127941 | S15: =R15*'2_Factores'!R31 -> 54650561 | T15: =S15*'2_Factores'!S31 -> 55243493 | U15: =T15*'2_Factores'!T31 -> 55859120 | V15: =U15*'2_Factores'!U31 -> 56426074 | W15: =V15*'2_Factores'!V31 -> 56800061 | X15: =W15*'2_Factores'!W31 -> 57079697 | ... AA15: =Z15*'2_Factores'!Z31 -> 57842440 | AB15: =AA15 -> 57842440 | AC15: ='1_Triangulo'!P15 -> 51927991 | AD15: =AB15-AC15 -> 5914448.8
A16: AO13 | B16: Q4 2020 | C16: ='1_Triangulo'!C16 -> 10087956 | D16: ='1_Triangulo'!D16 -> 15373929 | E16: ='1_Triangulo'!E16 -> 17870492 | F16: ='1_Triangulo'!F16 -> 23254623 | G16: ='1_Triangulo'!G16 -> 27462859 | H16: ='1_Triangulo'!H16 -> 33114279 | I16: ='1_Triangulo'!I16 -> 36827916 | J16: ='1_Triangulo'!J16 -> 41964520 | ... O16: ='1_Triangulo'!O16 -> 51522184 | P16: =O16*'2_Factores'!O31 -> 52675255 | Q16: =P16*'2_Factores'!P31 -> 53819321 | R16: =Q16*'2_Factores'!Q31 -> 54906864 | S16: =R16*'2_Factores'!R31 -> 55437005 | T16: =S16*'2_Factores'!S31 -> 56038469 | U16: =T16*'2_Factores'!T31 -> 56662955 | V16: =U16*'2_Factores'!U31 -> 57238068 | W16: =V16*'2_Factores'!V31 -> 57617436 | ... AA16: =Z16*'2_Factores'!Z31 -> 58674815 | AB16: =AA16 -> 58674815 | AC16: ='1_Triangulo'!O16 -> 51522184 | AD16: =AB16-AC16 -> 7152631.4
A17: AO14 | B17: Q1 2021 | C17: ='1_Triangulo'!C17 -> 9141610 | D17: ='1_Triangulo'!D17 -> 16200065 | E17: ='1_Triangulo'!E17 -> 19463623 | F17: ='1_Triangulo'!F17 -> 22713844 | G17: ='1_Triangulo'!G17 -> 28815023 | H17: ='1_Triangulo'!H17 -> 34375385 | I17: ='1_Triangulo'!I17 -> 38448539 | J17: ='1_Triangulo'!J17 -> 41701968 | ... N17: ='1_Triangulo'!N17 -> 51401276 | O17: =N17*'2_Factores'!N31 -> 52585832 | P17: =O17*'2_Factores'!O31 -> 53762708 | Q17: =P17*'2_Factores'!P31 -> 54930392 | R17: =Q17*'2_Factores'!Q31 -> 56040386 | S17: =R17*'2_Factores'!R31 -> 56581472 | T17: =S17*'2_Factores'!S31 -> 57195353 | U17: =T17*'2_Factores'!T31 -> 57832731 | V17: =U17*'2_Factores'!U31 -> 58419717 | ... AA17: =Z17*'2_Factores'!Z31 -> 59886126 | AB17: =AA17 -> 59886126 | AC17: ='1_Triangulo'!N17 -> 51401276 | AD17: =AB17-AC17 -> 8484849.5
A18: AO15 | B18: Q2 2021 | C18: ='1_Triangulo'!C18 -> 9809392 | D18: ='1_Triangulo'!D18 -> 14964880 | E18: ='1_Triangulo'!E18 -> 29456240 | F18: ='1_Triangulo'!F18 -> 21886059 | G18: ='1_Triangulo'!G18 -> 27984336 | H18: ='1_Triangulo'!H18 -> 33309956 | I18: ='1_Triangulo'!I18 -> 37548097 | J18: ='1_Triangulo'!J18 -> 44170211 | ... M18: ='1_Triangulo'!M18 -> 49785597 | N18: =M18*'2_Factores'!M31 -> 51907411 | O18: =N18*'2_Factores'!N31 -> 53103631 | P18: =O18*'2_Factores'!O31 -> 54292095 | Q18: =P18*'2_Factores'!P31 -> 55471277 | R18: =Q18*'2_Factores'!Q31 -> 56592202 | S18: =R18*'2_Factores'!R31 -> 57138615 | T18: =S18*'2_Factores'!S31 -> 57758540 | U18: =T18*'2_Factores'!T31 -> 58402195 | ... AA18: =Z18*'2_Factores'!Z31 -> 60475809 | AB18: =AA18 -> 60475809 | AC18: ='1_Triangulo'!M18 -> 49785597 | AD18: =AB18-AC18 -> 10690212
A19: AO16 | B19: Q3 2021 | C19: ='1_Triangulo'!C19 -> 10210239 | D19: ='1_Triangulo'!D19 -> 14903106 | E19: ='1_Triangulo'!E19 -> 20445946 | F19: ='1_Triangulo'!F19 -> 24098871 | G19: ='1_Triangulo'!G19 -> 28388139 | H19: ='1_Triangulo'!H19 -> 34217767 | I19: ='1_Triangulo'!I19 -> 38960082 | J19: ='1_Triangulo'!J19 -> 43388072 | ... L19: ='1_Triangulo'!L19 -> 46502204 | M19: =L19*'2_Factores'!L31 -> 49269347 | N19: =M19*'2_Factores'!M31 -> 51369159 | O19: =N19*'2_Factores'!N31 -> 52552974 | P19: =O19*'2_Factores'!O31 -> 53729115 | Q19: =P19*'2_Factores'!P31 -> 54896070 | R19: =Q19*'2_Factores'!Q31 -> 56005370 | S19: =R19*'2_Factores'!R31 -> 56546118 | T19: =S19*'2_Factores'!S31 -> 57159615 | ... AA19: =Z19*'2_Factores'!Z31 -> 59848706 | AB19: =AA19 -> 59848706 | AC19: ='1_Triangulo'!L19 -> 46502204 | AD19: =AB19-AC19 -> 13346502
A20: AO17 | B20: Q4 2021 | C20: ='1_Triangulo'!C20 -> 9812587 | D20: ='1_Triangulo'!D20 -> 15038280 | E20: ='1_Triangulo'!E20 -> 20982739 | F20: ='1_Triangulo'!F20 -> 23658407 | G20: ='1_Triangulo'!G20 -> 30806585 | H20: ='1_Triangulo'!H20 -> 33132506 | I20: ='1_Triangulo'!I20 -> 39260427 | J20: ='1_Triangulo'!J20 -> 44710406 | K20: ='1_Triangulo'!K20 -> 46743977 | L20: =K20*'2_Factores'!K31 -> 47378460 | M20: =L20*'2_Factores'!L31 -> 50197744 | N20: =M20*'2_Factores'!M31 -> 52337124 | O20: =N20*'2_Factores'!N31 -> 53543246 | P20: =O20*'2_Factores'!O31 -> 54741549 | Q20: =P20*'2_Factores'!P31 -> 55930493 | R20: =Q20*'2_Factores'!Q31 -> 57060697 | S20: =R20*'2_Factores'!R31 -> 57611634 | ... AA20: =Z20*'2_Factores'!Z31 -> 60976454 | AB20: =AA20 -> 60976454 | AC20: ='1_Triangulo'!K20 -> 46743977 | AD20: =AB20-AC20 -> 14232477
A21: AO18 | B21: Q1 2022 | C21: ='1_Triangulo'!C21 -> 9656222 | D21: ='1_Triangulo'!D21 -> 15173530 | E21: ='1_Triangulo'!E21 -> 19994922 | F21: ='1_Triangulo'!F21 -> 24377061 | G21: ='1_Triangulo'!G21 -> 30354330 | H21: ='1_Triangulo'!H21 -> 35076444 | I21: ='1_Triangulo'!I21 -> 39440849 | J21: ='1_Triangulo'!J21 -> 45510753 | K21: =J21*'2_Factores'!J31 -> 47720186 | L21: =K21*'2_Factores'!K31 -> 48367919 | M21: =L21*'2_Factores'!L31 -> 51246082 | N21: =M21*'2_Factores'!M31 -> 53430141 | O21: =N21*'2_Factores'!N31 -> 54661452 | P21: =O21*'2_Factores'!O31 -> 55884781 | Q21: =P21*'2_Factores'!P31 -> 57098555 | R21: =Q21*'2_Factores'!Q31 -> 58252362 | ... AA21: =Z21*'2_Factores'!Z31 -> 62249896 | AB21: =AA21 -> 62249896 | AC21: ='1_Triangulo'!J21 -> 45510753 | AD21: =AB21-AC21 -> 16739143
A22: AO19 | B22: Q2 2022 | C22: ='1_Triangulo'!C22 -> 10157249 | D22: ='1_Triangulo'!D22 -> 15227277 | E22: ='1_Triangulo'!E22 -> 20949821 | F22: ='1_Triangulo'!F22 -> 24555011 | G22: ='1_Triangulo'!G22 -> 29825871 | H22: ='1_Triangulo'!H22 -> 35812219 | I22: ='1_Triangulo'!I22 -> 40828576 | J22: =I22*'2_Factores'!I31 -> 45965418 | K22: =J22*'2_Factores'!J31 -> 48196923 | L22: =K22*'2_Factores'!K31 -> 48851128 | M22: =L22*'2_Factores'!L31 -> 51758044 | N22: =M22*'2_Factores'!M31 -> 53963922 | O22: =N22*'2_Factores'!N31 -> 55207535 | P22: =O22*'2_Factores'!O31 -> 56443085 | Q22: =P22*'2_Factores'!P31 -> 57668985 | ... AA22: =Z22*'2_Factores'!Z31 -> 62871790 | AB22: =AA22 -> 62871790 | AC22: ='1_Triangulo'!I22 -> 40828576 | AD22: =AB22-AC22 -> 22043214
A23: AO20 | B23: Q3 2022 | C23: ='1_Triangulo'!C23 -> 10159861 | D23: ='1_Triangulo'!D23 -> 14850703 | E23: ='1_Triangulo'!E23 -> 21643786 | F23: ='1_Triangulo'!F23 -> 25037048 | G23: ='1_Triangulo'!G23 -> 30971544 | H23: ='1_Triangulo'!H23 -> 35649464 | I23: =H23*'2_Factores'!H31 -> 40609938 | J23: =I23*'2_Factores'!I31 -> 45719272 | K23: =J23*'2_Factores'!J31 -> 47938827 | L23: =K23*'2_Factores'!K31 -> 48589529 | M23: =L23*'2_Factores'!L31 -> 51480879 | N23: =M23*'2_Factores'!M31 -> 53674944 | O23: =N23*'2_Factores'!N31 -> 54911897 | P23: =O23*'2_Factores'!O31 -> 56140830 | ... AA23: =Z23*'2_Factores'!Z31 -> 62535109 | AB23: =AA23 -> 62535109 | AC23: ='1_Triangulo'!H23 -> 35649464 | AD23: =AB23-AC23 -> 26885645
A24: AO21 | B24: Q4 2022 | C24: ='1_Triangulo'!C24 -> 10216038 | D24: ='1_Triangulo'!D24 -> 15551970 | E24: ='1_Triangulo'!E24 -> 21643436 | F24: ='1_Triangulo'!F24 -> 26300255 | G24: ='1_Triangulo'!G24 -> 31915838 | H24: =G24*'2_Factores'!G31 -> 37465926 | I24: =H24*'2_Factores'!H31 -> 42679153 | J24: =I24*'2_Factores'!I31 -> 48048825 | K24: =J24*'2_Factores'!J31 -> 50381475 | L24: =K24*'2_Factores'!K31 -> 51065331 | M24: =L24*'2_Factores'!L31 -> 54104005 | N24: =M24*'2_Factores'!M31 -> 56409866 | O24: =N24*'2_Factores'!N31 -> 57709846 | ... AA24: =Z24*'2_Factores'!Z31 -> 65721487 | AB24: =AA24 -> 65721487 | AC24: ='1_Triangulo'!G24 -> 31915838 | AD24: =AB24-AC24 -> 33805649
A25: AO22 | B25: Q1 2023 | C25: ='1_Triangulo'!C25 -> 10453025 | D25: ='1_Triangulo'!D25 -> 15565827 | E25: ='1_Triangulo'!E25 -> 21209178 | F25: ='1_Triangulo'!F25 -> 26324052 | G25: =F25*'2_Factores'!F31 -> 31958258 | H25: =G25*'2_Factores'!G31 -> 37515723 | I25: =H25*'2_Factores'!H31 -> 42735879 | J25: =I25*'2_Factores'!I31 -> 48112687 | K25: =J25*'2_Factores'!J31 -> 50448438 | L25: =K25*'2_Factores'!K31 -> 51133203 | M25: =L25*'2_Factores'!L31 -> 54175916 | N25: =M25*'2_Factores'!M31 -> 56484841 | ... AA25: =Z25*'2_Factores'!Z31 -> 65808839 | AB25: =AA25 -> 65808839 | AC25: ='1_Triangulo'!F25 -> 26324052 | AD25: =AB25-AC25 -> 39484787
A26: AO23 | B26: Q2 2023 | C26: ='1_Triangulo'!C26 -> 10530025 | D26: ='1_Triangulo'!D26 -> 16254730 | E26: ='1_Triangulo'!E26 -> 22079496 | F26: =E26*'2_Factores'!E31 -> 26747784 | G26: =F26*'2_Factores'!F31 -> 32472682 | H26: =G26*'2_Factores'!G31 -> 38119604 | I26: =H26*'2_Factores'!H31 -> 43423787 | J26: =I26*'2_Factores'!I31 -> 48887145 | K26: =J26*'2_Factores'!J31 -> 51260493 | L26: =K26*'2_Factores'!K31 -> 51956281 | M26: =L26*'2_Factores'!L31 -> 55047972 | ... AA26: =Z26*'2_Factores'!Z31 -> 66868147 | AB26: =AA26 -> 66868147 | AC26: ='1_Triangulo'!E26 -> 22079496 | AD26: =AB26-AC26 -> 44788651
A27: AO24 | B27: Q3 2023 | C27: ='1_Triangulo'!C27 -> 10382200 | D27: ='1_Triangulo'!D27 -> 17132382 | E27: =D27*'2_Factores'!D31 -> 22411595 | F27: =E27*'2_Factores'!E31 -> 27150098 | G27: =F27*'2_Factores'!F31 -> 32961105 | H27: =G27*'2_Factores'!G31 -> 38692963 | I27: =H27*'2_Factores'!H31 -> 44076927 | J27: =I27*'2_Factores'!I31 -> 49622459 | K27: =J27*'2_Factores'!J31 -> 52031505 | L27: =K27*'2_Factores'!K31 -> 52737759 | ... AA27: =Z27*'2_Factores'!Z31 -> 67873914 | AB27: =AA27 -> 67873914 | AC27: ='1_Triangulo'!D27 -> 17132382 | AD27: =AB27-AC27 -> 50741532
A28: AO25 | B28: Q4 2023 | C28: ='1_Triangulo'!C28 -> 10443357 | D28: =C28*'2_Factores'!C31 -> 16407714 | E28: =D28*'2_Factores'!D31 -> 21463626 | F28: =E28*'2_Factores'!E31 -> 26001699 | G28: =F28*'2_Factores'!F31 -> 31566911 | H28: =G28*'2_Factores'!G31 -> 37056322 | I28: =H28*'2_Factores'!H31 -> 42212554 | J28: =I28*'2_Factores'!I31 -> 47523521 | K28: =J28*'2_Factores'!J31 -> 49830668 | ... AA28: =Z28*'2_Factores'!Z31 -> 65002973 | AB28: =AA28 -> 65002973 | AC28: ='1_Triangulo'!C28 -> 10443357 | AD28: =AB28-AC28 -> 54559616
A29: TOTAL IBNR CL | AA29: TOTAL IBNR CL | AB29: =SUM(AB4:AB28) -> 1.466375e+09 | AD29: =SUM(AD4:AD28) -> 3.6811687e+08

Sheet 4_BF
A1: BORNHUETTER-FERGUSON · IBNR_BF = Apriori × (1−%Des) · ELR en B4 · Vinculado a hojas 1,2,3
A2: %Des vinculado a 2_Factores · Pagado y prima de 1_Triangulo · Último_CL de 3_ChainLadder
A4: ELR a priori (BF): | B4: 0.68 | C4: ← Modifica este valor para sensibilizar el IBNR BF
A7: AO | B7: Trim. | C7: Pagado actual (diagonal) | D7: Prima Devengada | E7: % Des. (de 2_Factores) | F7: % No-Des. =1−%Des | G7: Apriori =Prima×ELR | H7: IBNR_BF =Apriori×%NoDes | I7: Último_BF =Pag+IBNR | J7: Último_CL (ref.hoja3) | K7: Diferencia BF−CL
A8: AO01 | B8: Q4 2017 | C8: ='1_Triangulo'!AA4 -> 49970260 | D8: ='1_Triangulo'!AC4 -> 74396187 | E8: =1 -> 1 | F8: =0 -> 0 | G8: =D8*$B$4 -> 50589407 | H8: =G8*F8 -> 0 | I8: =C8+H8 -> 49970260 | J8: ='3_ChainLadder'!AB4 -> 49970260 | K8: =H8-'3_ChainLadder'!AD4 -> 0
A9: AO02 | B9: Q1 2018 | C9: ='1_Triangulo'!Z5 -> 50579274 | D9: ='1_Triangulo'!AC5 -> 73564016 | E9: ='2_Factores'!Z34 -> 0.99648933 | F9: =1-E9 -> 0.0035106681 | G9: =D9*$B$4 -> 50023531 | H9: =G9*F9 -> 175616.02 | I9: =C9+H9 -> 50754890 | J9: ='3_ChainLadder'!AB5 -> 50757467 | K9: =H9-'3_ChainLadder'!AD5 -> -2576.6048
A10: AO03 | B10: Q2 2018 | C10: ='1_Triangulo'!Y6 -> 51107802 | D10: ='1_Triangulo'!AC6 -> 74286643 | E10: ='2_Factores'!Y34 -> 0.99319676 | F10: =1-E10 -> 0.0068032372 | G10: =D10*$B$4 -> 50514917 | H10: =G10*F10 -> 343664.97 | I10: =C10+H10 -> 51451467 | J10: ='3_ChainLadder'!AB6 -> 51457882 | K10: =H10-'3_ChainLadder'!AD6 -> -6415.2142
A11: AO04 | B11: Q3 2018 | C11: ='1_Triangulo'!X7 -> 51395178 | D11: ='1_Triangulo'!AC7 -> 76777775 | E11: ='2_Factores'!X34 -> 0.98681344 | F11: =1-E11 -> 0.013186561 | G11: =D11*$B$4 -> 52208887 | H11: =G11*F11 -> 688455.67 | I11: =C11+H11 -> 52083634 | J11: ='3_ChainLadder'!AB7 -> 52081960 | K11: =H11-'3_ChainLadder'!AD7 -> 1673.7314
A12: AO05 | B12: Q4 2018 | C12: ='1_Triangulo'!W8 -> 52457834 | D12: ='1_Triangulo'!AC8 -> 78595028 | E12: ='2_Factores'!W34 -> 0.981979 | F12: =1-E12 -> 0.018021004 | G12: =D12*$B$4 -> 53444619 | H12: =G12*F12 -> 963125.71 | I12: =C12+H12 -> 53420960 | J12: ='3_ChainLadder'!AB8 -> 53420526 | K12: =H12-'3_ChainLadder'!AD8 -> 434.1894
A13: AO06 | B13: Q1 2019 | C13: ='1_Triangulo'!V9 -> 52189573 | D13: ='1_Triangulo'!AC9 -> 78256129 | E13: ='2_Factores'!V34 -> 0.97551338 | F13: =1-E13 -> 0.024486619 | G13: =D13*$B$4 -> 53214168 | H13: =G13*F13 -> 1303035.1 | I13: =C13+H13 -> 53492608 | J13: ='3_ChainLadder'!AB9 -> 53499597 | K13: =H13-'3_ChainLadder'!AD9 -> -6989.2047
A14: AO07 | B14: Q2 2019 | C14: ='1_Triangulo'!U10 -> 52496431 | D14: ='1_Triangulo'!AC10 -> 81976635 | E14: ='2_Factores'!U34 -> 0.96571169 | F14: =1-E14 -> 0.034288315 | G14: =D14*$B$4 -> 55744112 | H14: =G14*F14 -> 1911371.7 | I14: =C14+H14 -> 54407803 | J14: ='3_ChainLadder'!AB10 -> 54360356 | K14: =H14-'3_ChainLadder'!AD10 -> 47446.655
A15: AO08 | B15: Q3 2019 | C15: ='1_Triangulo'!T11 -> 52493077 | D15: ='1_Triangulo'!AC11 -> 81647448 | E15: ='2_Factores'!T34 -> 0.95506851 | F15: =1-E15 -> 0.04493149 | G15: =D15*$B$4 -> 55520265 | H15: =G15*F15 -> 2494608.2 | I15: =C15+H15 -> 54987685 | J15: ='3_ChainLadder'!AB11 -> 54962630 | K15: =H15-'3_ChainLadder'!AD11 -> 25055.361
A16: AO09 | B16: Q4 2019 | C16: ='1_Triangulo'!S12 -> 52617714 | D16: ='1_Triangulo'!AC12 -> 81746441 | E16: ='2_Factores'!S34 -> 0.94481771 | F16: =1-E16 -> 0.055182293 | G16: =D16*$B$4 -> 55587580 | H16: =G16*F16 -> 3067450.1 | I16: =C16+H16 -> 55685164 | J16: ='3_ChainLadder'!AB12 -> 55690864 | K16: =H16-'3_ChainLadder'!AD12 -> -5699.4296
A17: AO10 | B17: Q1 2020 | C17: ='1_Triangulo'!R13 -> 52625937 | D17: ='1_Triangulo'!AC13 -> 82405997 | E17: ='2_Factores'!R34 -> 0.93578247 | F17: =1-E17 -> 0.06421753 | G17: =D17*$B$4 -> 56036078 | H17: =G17*F17 -> 3598498.5 | I17: =C17+H17 -> 56224436 | J17: ='3_ChainLadder'!AB13 -> 56237361 | K17: =H17-'3_ChainLadder'!AD13 -> -12925.93
A18: AO11 | B18: Q2 2020 | C18: ='1_Triangulo'!Q14 -> 52557910 | D18: ='1_Triangulo'!AC14 -> 83269600 | E18: ='2_Factores'!Q34 -> 0.91724739 | F18: =1-E18 -> 0.082752613 | G18: =D18*$B$4 -> 56623328 | H18: =G18*F18 -> 4685728.3 | I18: =C18+H18 -> 57243638 | J18: ='3_ChainLadder'!AB14 -> 57299602 | K18: =H18-'3_ChainLadder'!AD14 -> -55963.421
A19: AO12 | B19: Q3 2020 | C19: ='1_Triangulo'!P15 -> 51927991 | D19: ='1_Triangulo'!AC15 -> 86364093 | E19: ='2_Factores'!P34 -> 0.89774897 | F19: =1-E19 -> 0.10225103 | G19: =D19*$B$4 -> 58727583 | H19: =G19*F19 -> 6004955.6 | I19: =C19+H19 -> 57932947 | J19: ='3_ChainLadder'!AB15 -> 57842440 | K19: =H19-'3_ChainLadder'!AD15 -> 90506.822
A20: AO13 | B20: Q4 2020 | C20: ='1_Triangulo'!O16 -> 51522184 | D20: ='1_Triangulo'!AC16 -> 86023052 | E20: ='2_Factores'!O34 -> 0.87809708 | F20: =1-E20 -> 0.12190292 | G20: =D20*$B$4 -> 58495675 | H20: =G20*F20 -> 7130793.7 | I20: =C20+H20 -> 58652978 | J20: ='3_ChainLadder'!AB16 -> 58674815 | K20: =H20-'3_ChainLadder'!AD16 -> -21837.697
A21: AO14 | B21: Q1 2021 | C21: ='1_Triangulo'!N17 -> 51401276 | D21: ='1_Triangulo'!AC17 -> 85192925 | E21: ='2_Factores'!N34 -> 0.85831694 | F21: =1-E21 -> 0.14168306 | G21: =D21*$B$4 -> 57931189 | H21: =G21*F21 -> 8207868.2 | I21: =C21+H21 -> 59609144 | J21: ='3_ChainLadder'!AB17 -> 59886126 | K21: =H21-'3_ChainLadder'!AD17 -> -276981.39
A22: AO15 | B22: Q2 2021 | C22: ='1_Triangulo'!M18 -> 49785597 | D22: ='1_Triangulo'!AC18 -> 88141373 | E22: ='2_Factores'!M34 -> 0.82323161 | F22: =1-E22 -> 0.17676839 | G22: =D22*$B$4 -> 59936134 | H22: =G22*F22 -> 10594814 | I22: =C22+H22 -> 60380411 | J22: ='3_ChainLadder'!AB18 -> 60475809 | K22: =H22-'3_ChainLadder'!AD18 -> -95397.475
A23: AO16 | B23: Q3 2021 | C23: ='1_Triangulo'!L19 -> 46502204 | D23: ='1_Triangulo'!AC19 -> 91162359 | E23: ='2_Factores'!L34 -> 0.77699598 | F23: =1-E23 -> 0.22300402 | G23: =D23*$B$4 -> 61990404 | H23: =G23*F23 -> 13824109 | I23: =C23+H23 -> 60326314 | J23: ='3_ChainLadder'!AB19 -> 59848706 | K23: =H23-'3_ChainLadder'!AD19 -> 477607.18
A24: AO17 | B24: Q4 2021 | C24: ='1_Triangulo'!K20 -> 46743977 | D24: ='1_Triangulo'!AC20 -> 89354737 | E24: ='2_Factores'!K34 -> 0.76659061 | F24: =1-E24 -> 0.23340939 | G24: =D24*$B$4 -> 60761221 | H24: =G24*F24 -> 14182240 | I24: =C24+H24 -> 60926217 | J24: ='3_ChainLadder'!AB20 -> 60976454 | K24: =H24-'3_ChainLadder'!AD20 -> -50237.425
A25: AO18 | B25: Q1 2022 | C25: ='1_Triangulo'!J21 -> 45510753 | D25: ='1_Triangulo'!AC21 -> 90519813 | E25: ='2_Factores'!J34 -> 0.73109765 | F25: =1-E25 -> 0.26890235 | G25: =D25*$B$4 -> 61553473 | H25: =G25*F25 -> 16551874 | I25: =C25+H25 -> 62062627 | J25: ='3_ChainLadder'!AB21 -> 62249896 | K25: =H25-'3_ChainLadder'!AD21 -> -187269.95
A26: AO19 | B26: Q2 2022 | C26: ='1_Triangulo'!I22 -> 40828576 | D26: ='1_Triangulo'!AC22 -> 93738616 | E26: ='2_Factores'!I34 -> 0.64939421 | F26: =1-E26 -> 0.35060579 | G26: =D26*$B$4 -> 63742259 | H26: =G26*F26 -> 22348405 | I26: =C26+H26 -> 63176981 | J26: ='3_ChainLadder'!AB22 -> 62871790 | K26: =H26-'3_ChainLadder'!AD22 -> 305191.53
A27: AO20 | B27: Q3 2022 | C27: ='1_Triangulo'!H23 -> 35649464 | D27: ='1_Triangulo'!AC23 -> 95003331 | E27: ='2_Factores'!H34 -> 0.57007119 | F27: =1-E27 -> 0.42992881 | G27: =D27*$B$4 -> 64602265 | H27: =G27*F27 -> 27774375 | I27: =C27+H27 -> 63423839 | J27: ='3_ChainLadder'!AB23 -> 62535109 | K27: =H27-'3_ChainLadder'!AD23 -> 888729.78
A28: AO21 | B28: Q4 2022 | C28: ='1_Triangulo'!G24 -> 31915838 | D28: ='1_Triangulo'!AC24 -> 96874956 | E28: ='2_Factores'!G34 -> 0.48562258 | F28: =1-E28 -> 0.51437742 | G28: =D28*$B$4 -> 65874970 | H28: =G28*F28 -> 33884597 | I28: =C28+H28 -> 65800435 | J28: ='3_ChainLadder'!AB24 -> 65721487 | K28: =H28-'3_ChainLadder'!AD24 -> 78948.158
A29: AO22 | B29: Q1 2023 | C29: ='1_Triangulo'!F25 -> 26324052 | D29: ='1_Triangulo'!AC25 -> 99436938 | E29: ='2_Factores'!F34 -> 0.40000785 | F29: =1-E29 -> 0.59999215 | G29: =D29*$B$4 -> 67617118 | H29: =G29*F29 -> 40569740 | I29: =C29+H29 -> 66893792 | J29: ='3_ChainLadder'!AB25 -> 65808839 | K29: =H29-'3_ChainLadder'!AD25 -> 1084953.2
A30: AO23 | B30: Q2 2023 | C30: ='1_Triangulo'!E26 -> 22079496 | D30: ='1_Triangulo'!AC26 -> 100036702 | E30: ='2_Factores'!E34 -> 0.33019452 | F30: =1-E30 -> 0.66980548 | G30: =D30*$B$4 -> 68024957 | H30: =G30*F30 -> 45563489 | I30: =C30+H30 -> 67642985 | J30: ='3_ChainLadder'!AB26 -> 66868147 | K30: =H30-'3_ChainLadder'!AD26 -> 774837.93
A31: AO24 | B31: Q3 2023 | C31: ='1_Triangulo'!D27 -> 17132382 | D31: ='1_Triangulo'!AC27 -> 100703868 | E31: ='2_Factores'!D34 -> 0.25241482 | F31: =1-E31 -> 0.74758518 | G31: =D31*$B$4 -> 68478630 | H31: =G31*F31 -> 51193609 | I31: =C31+H31 -> 68325991 | J31: ='3_ChainLadder'!AB27 -> 67873914 | K31: =H31-'3_ChainLadder'!AD27 -> 452076.56
A32: AO25 | B32: Q4 2023 | C32: ='1_Triangulo'!C28 -> 10443357 | D32: ='1_Triangulo'!AC28 -> 102738652 | E32: ='2_Factores'!C34 -> 0.16065968 | F32: =1-E32 -> 0.83934032 | G32: =D32*$B$4 -> 69862283 | H32: =G32*F32 -> 58638231 | I32: =C32+H32 -> 69081588 | J32: ='3_ChainLadder'!AB28 -> 65002973 | K32: =H32-'3_ChainLadder'!AD28 -> 4078615.2
A33: TOTAL | H33: =SUM(H8:H32) -> 3.7570066e+08 | I33: =SUM(I8:I32) -> 1.4739588e+09 | J33: =SUM(J8:J32) -> 1.466375e+09 | K33: =SUM(K8:K32) -> 7583782.6

Sheet 5_CapeCod
A1: CAPE COD · ELR_CC = Σ Pagados / Σ(Prima×%Des) · ELR endógeno calculado en B4
A2: ELR_CC en B4 calculado automáticamente · % Des de 4_BF · Primas de 1_Triangulo
A4: ELR Cape Cod: | B4: =SUM(C8:C32)/SUM(G8:G32) -> 0.67805752 | C4: Σ Pagados / Σ(Prima×%Des) — se actualiza automáticamente
A7: AO | B7: Trim. | C7: Pagado actual | D7: Prima Devengada | E7: % Des. | F7: % No-Des. | G7: Prima × %Des | H7: IBNR_CC =Prima×%NoDes×ELR_CC | I7: Último_CC | J7: Último_CL | K7: Diferencia CC−CL
A8: AO01 | B8: Q4 2017 | C8: ='1_Triangulo'!AA4 -> 49970260 | D8: ='1_Triangulo'!AC4 -> 74396187 | E8: ='4_BF'!E8 -> 1 | F8: =1-E8 -> 0 | G8: =D8*E8 -> 74396187 | H8: =D8*F8*$B$4 -> 0 | I8: =C8+H8 -> 49970260 | J8: ='3_ChainLadder'!AB4 -> 49970260 | K8: =H8-'3_ChainLadder'!AD4 -> 0
A9: AO02 | B9: Q1 2018 | C9: ='1_Triangulo'!Z5 -> 50579274 | D9: ='1_Triangulo'!AC5 -> 73564016 | E9: ='4_BF'!E9 -> 0.99648933 | F9: =1-E9 -> 0.0035106681 | G9: =D9*E9 -> 73305757 | H9: =D9*F9*$B$4 -> 175114.35 | I9: =C9+H9 -> 50754388 | J9: ='3_ChainLadder'!AB5 -> 50757467 | K9: =H9-'3_ChainLadder'!AD5 -> -3078.2678
A10: AO03 | B10: Q2 2018 | C10: ='1_Triangulo'!Y6 -> 51107802 | D10: ='1_Triangulo'!AC6 -> 74286643 | E10: ='4_BF'!E10 -> 0.99319676 | F10: =1-E10 -> 0.0068032372 | G10: =D10*E10 -> 73781253 | H10: =D10*F10*$B$4 -> 342683.26 | I10: =C10+H10 -> 51450485 | J10: ='3_ChainLadder'!AB6 -> 51457882 | K10: =H10-'3_ChainLadder'!AD6 -> -7396.9241
A11: AO04 | B11: Q3 2018 | C11: ='1_Triangulo'!X7 -> 51395178 | D11: ='1_Triangulo'!AC7 -> 76777775 | E11: ='4_BF'!E11 -> 0.98681344 | F11: =1-E11 -> 0.013186561 | G11: =D11*E11 -> 75765340 | H11: =D11*F11*$B$4 -> 686489.03 | I11: =C11+H11 -> 52081667 | J11: ='3_ChainLadder'!AB7 -> 52081960 | K11: =H11-'3_ChainLadder'!AD7 -> -292.90413
A12: AO05 | B12: Q4 2018 | C12: ='1_Triangulo'!W8 -> 52457834 | D12: ='1_Triangulo'!AC8 -> 78595028 | E12: ='4_BF'!E12 -> 0.981979 | F12: =1-E12 -> 0.018021004 | G12: =D12*E12 -> 77178667 | H12: =D12*F12*$B$4 -> 960374.46 | I12: =C12+H12 -> 53418208 | J12: ='3_ChainLadder'!AB8 -> 53420526 | K12: =H12-'3_ChainLadder'!AD8 -> -2317.0659
A13: AO06 | B13: Q1 2019 | C13: ='1_Triangulo'!V9 -> 52189573 | D13: ='1_Triangulo'!AC9 -> 78256129 | E13: ='4_BF'!E13 -> 0.97551338 | F13: =1-E13 -> 0.024486619 | G13: =D13*E13 -> 76339901 | H13: =D13*F13*$B$4 -> 1299312.8 | I13: =C13+H13 -> 53488886 | J13: ='3_ChainLadder'!AB9 -> 53499597 | K13: =H13-'3_ChainLadder'!AD9 -> -10711.442
A14: AO07 | B14: Q2 2019 | C14: ='1_Triangulo'!U10 -> 52496431 | D14: ='1_Triangulo'!AC10 -> 81976635 | E14: ='4_BF'!E14 -> 0.96571169 | F14: =1-E14 -> 0.034288315 | G14: =D14*E14 -> 79165794 | H14: =D14*F14*$B$4 -> 1905911.6 | I14: =C14+H14 -> 54402343 | J14: ='3_ChainLadder'!AB10 -> 54360356 | K14: =H14-'3_ChainLadder'!AD10 -> 41986.649
A15: AO08 | B15: Q3 2019 | C15: ='1_Triangulo'!T11 -> 52493077 | D15: ='1_Triangulo'!AC11 -> 81647448 | E15: ='4_BF'!E15 -> 0.95506851 | F15: =1-E15 -> 0.04493149 | G15: =D15*E15 -> 77978906 | H15: =D15*F15*$B$4 -> 2487482.2 | I15: =C15+H15 -> 54980559 | J15: ='3_ChainLadder'!AB11 -> 54962630 | K15: =H15-'3_ChainLadder'!AD11 -> 17929.288
A16: AO09 | B16: Q4 2019 | C16: ='1_Triangulo'!S12 -> 52617714 | D16: ='1_Triangulo'!AC12 -> 81746441 | E16: ='4_BF'!E16 -> 0.94481771 | F16: =1-E16 -> 0.055182293 | G16: =D16*E16 -> 77235485 | H16: =D16*F16*$B$4 -> 3058687.7 | I16: =C16+H16 -> 55676402 | J16: ='3_ChainLadder'!AB12 -> 55690864 | K16: =H16-'3_ChainLadder'!AD12 -> -14461.877
A17: AO10 | B17: Q1 2020 | C17: ='1_Triangulo'!R13 -> 52625937 | D17: ='1_Triangulo'!AC13 -> 82405997 | E17: ='4_BF'!E17 -> 0.93578247 | F17: =1-E17 -> 0.06421753 | G17: =D17*E17 -> 77114087 | H17: =D17*F17*$B$4 -> 3588219.1 | I17: =C17+H17 -> 56214156 | J17: ='3_ChainLadder'!AB13 -> 56237361 | K17: =H17-'3_ChainLadder'!AD13 -> -23205.365
A18: AO11 | B18: Q2 2020 | C18: ='1_Triangulo'!Q14 -> 52557910 | D18: ='1_Triangulo'!AC14 -> 83269600 | E18: ='4_BF'!E18 -> 0.91724739 | F18: =1-E18 -> 0.082752613 | G18: =D18*E18 -> 76378823 | H18: =D18*F18*$B$4 -> 4672343.1 | I18: =C18+H18 -> 57230253 | J18: ='3_ChainLadder'!AB14 -> 57299602 | K18: =H18-'3_ChainLadder'!AD14 -> -69348.626
A19: AO12 | B19: Q3 2020 | C19: ='1_Triangulo'!P15 -> 51927991 | D19: ='1_Triangulo'!AC15 -> 86364093 | E19: ='4_BF'!E19 -> 0.89774897 | F19: =1-E19 -> 0.10225103 | G19: =D19*E19 -> 77533276 | H19: =D19*F19*$B$4 -> 5987802 | I19: =C19+H19 -> 57915793 | J19: ='3_ChainLadder'!AB15 -> 57842440 | K19: =H19-'3_ChainLadder'!AD15 -> 73353.126
A20: AO13 | B20: Q4 2020 | C20: ='1_Triangulo'!O16 -> 51522184 | D20: ='1_Triangulo'!AC16 -> 86023052 | E20: ='4_BF'!E20 -> 0.87809708 | F20: =1-E20 -> 0.12190292 | G20: =D20*E20 -> 75536591 | H20: =D20*F20*$B$4 -> 7110424 | I20: =C20+H20 -> 58632608 | J20: ='3_ChainLadder'!AB16 -> 58674815 | K20: =H20-'3_ChainLadder'!AD16 -> -42207.451
A21: AO14 | B21: Q1 2021 | C21: ='1_Triangulo'!N17 -> 51401276 | D21: ='1_Triangulo'!AC17 -> 85192925 | E21: ='4_BF'!E21 -> 0.85831694 | F21: =1-E21 -> 0.14168306 | G21: =D21*E21 -> 73122531 | H21: =D21*F21*$B$4 -> 8184421.6 | I21: =C21+H21 -> 59585698 | J21: ='3_ChainLadder'!AB17 -> 59886126 | K21: =H21-'3_ChainLadder'!AD17 -> -300427.91
A22: AO15 | B22: Q2 2021 | C22: ='1_Triangulo'!M18 -> 49785597 | D22: ='1_Triangulo'!AC18 -> 88141373 | E22: ='4_BF'!E22 -> 0.82323161 | F22: =1-E22 -> 0.17676839 | G22: =D22*E22 -> 72560764 | H22: =D22*F22*$B$4 -> 10564549 | I22: =C22+H22 -> 60350146 | J22: ='3_ChainLadder'!AB18 -> 60475809 | K22: =H22-'3_ChainLadder'!AD18 -> -125662.51
A23: AO16 | B23: Q3 2021 | C23: ='1_Triangulo'!L19 -> 46502204 | D23: ='1_Triangulo'!AC19 -> 91162359 | E23: ='4_BF'!E23 -> 0.77699598 | F23: =1-E23 -> 0.22300402 | G23: =D23*E23 -> 70832786 | H23: =D23*F23*$B$4 -> 13784620 | I23: =C23+H23 -> 60286824 | J23: ='3_ChainLadder'!AB19 -> 59848706 | K23: =H23-'3_ChainLadder'!AD19 -> 438117.37
A24: AO17 | B24: Q4 2021 | C24: ='1_Triangulo'!K20 -> 46743977 | D24: ='1_Triangulo'!AC20 -> 89354737 | E24: ='4_BF'!E24 -> 0.76659061 | F24: =1-E24 -> 0.23340939 | G24: =D24*E24 -> 68498502 | H24: =D24*F24*$B$4 -> 14141727 | I24: =C24+H24 -> 60885704 | J24: ='3_ChainLadder'!AB20 -> 60976454 | K24: =H24-'3_ChainLadder'!AD20 -> -90750.27
A25: AO18 | B25: Q1 2022 | C25: ='1_Triangulo'!J21 -> 45510753 | D25: ='1_Triangulo'!AC21 -> 90519813 | E25: ='4_BF'!E25 -> 0.73109765 | F25: =1-E25 -> 0.26890235 | G25: =D25*E25 -> 66178823 | H25: =D25*F25*$B$4 -> 16504592 | I25: =C25+H25 -> 62015345 | J25: ='3_ChainLadder'!AB21 -> 62249896 | K25: =H25-'3_ChainLadder'!AD21 -> -234551.86
A26: AO19 | B26: Q2 2022 | C26: ='1_Triangulo'!I22 -> 40828576 | D26: ='1_Triangulo'!AC22 -> 93738616 | E26: ='4_BF'!E26 -> 0.64939421 | F26: =1-E26 -> 0.35060579 | G26: =D26*E26 -> 60873314 | H26: =D26*F26*$B$4 -> 22284565 | I26: =C26+H26 -> 63113141 | J26: ='3_ChainLadder'!AB22 -> 62871790 | K26: =H26-'3_ChainLadder'!AD22 -> 241351.3
A27: AO20 | B27: Q3 2022 | C27: ='1_Triangulo'!H23 -> 35649464 | D27: ='1_Triangulo'!AC23 -> 95003331 | E27: ='4_BF'!E27 -> 0.57007119 | F27: =1-E27 -> 0.42992881 | G27: =D27*E27 -> 54158662 | H27: =D27*F27*$B$4 -> 27695035 | I27: =C27+H27 -> 63344499 | J27: ='3_ChainLadder'!AB23 -> 62535109 | K27: =H27-'3_ChainLadder'!AD23 -> 809389.78
A28: AO21 | B28: Q4 2022 | C28: ='1_Triangulo'!G24 -> 31915838 | D28: ='1_Triangulo'!AC24 -> 96874956 | E28: ='4_BF'!E28 -> 0.48562258 | F28: =1-E28 -> 0.51437742 | G28: =D28*E28 -> 47044666 | H28: =D28*F28*$B$4 -> 33787803 | I28: =C28+H28 -> 65703641 | J28: ='3_ChainLadder'!AB24 -> 65721487 | K28: =H28-'3_ChainLadder'!AD24 -> -17846.243
A29: AO22 | B29: Q1 2023 | C29: ='1_Triangulo'!F25 -> 26324052 | D29: ='1_Triangulo'!AC25 -> 99436938 | E29: ='4_BF'!E29 -> 0.40000785 | F29: =1-E29 -> 0.59999215 | G29: =D29*E29 -> 39775556 | H29: =D29*F29*$B$4 -> 40453849 | I29: =C29+H29 -> 66777901 | J29: ='3_ChainLadder'!AB25 -> 65808839 | K29: =H29-'3_ChainLadder'!AD25 -> 969062.13
A30: AO23 | B30: Q2 2023 | C30: ='1_Triangulo'!E26 -> 22079496 | D30: ='1_Triangulo'!AC26 -> 100036702 | E30: ='4_BF'!E30 -> 0.33019452 | F30: =1-E30 -> 0.66980548 | G30: =D30*E30 -> 33031571 | H30: =D30*F30*$B$4 -> 45433333 | I30: =C30+H30 -> 67512829 | J30: ='3_ChainLadder'!AB26 -> 66868147 | K30: =H30-'3_ChainLadder'!AD26 -> 644681.73
A31: AO24 | B31: Q3 2023 | C31: ='1_Triangulo'!D27 -> 17132382 | D31: ='1_Triangulo'!AC27 -> 100703868 | E31: ='4_BF'!E31 -> 0.25241482 | F31: =1-E31 -> 0.74758518 | G31: =D31*E31 -> 25419149 | H31: =D31*F31*$B$4 -> 51047370 | I31: =C31+H31 -> 68179752 | J31: ='3_ChainLadder'!AB27 -> 67873914 | K31: =H31-'3_ChainLadder'!AD27 -> 305837.41
A32: AO25 | B32: Q4 2023 | C32: ='1_Triangulo'!C28 -> 10443357 | D32: ='1_Triangulo'!AC28 -> 102738652 | E32: ='4_BF'!E32 -> 0.16065968 | F32: =1-E32 -> 0.83934032 | G32: =D32*E32 -> 16505959 | H32: =D32*F32*$B$4 -> 58470726 | I32: =C32+H32 -> 68914083 | J32: ='3_ChainLadder'!AB28 -> 65002973 | K32: =H32-'3_ChainLadder'!AD28 -> 3911109.8
A33: TOTAL | G33: =SUM(G8:G32) -> 1.6197124e+09 | H33: =SUM(H8:H32) -> 3.7462743e+08 | I33: =SUM(I8:I32) -> 1.4728856e+09 | J33: =SUM(J8:J32) -> 1.466375e+09 | K33: =SUM(K8:K32) -> 6510559.8

Sheet 6_Resumen
A1: RESUMEN COMPARATIVO — Chain-Ladder · Bornhuetter-Ferguson · Cape Cod
A3: ELR BF (a priori): | B3: ='4_BF'!B4 -> 0.68 | C3: ELR CC (endógeno): | D3: ='5_CapeCod'!B4 -> 0.67805752 | E3: Diferencia ELR: | F3: =D3-B3 -> -0.0019424812
A7: AO | B7: Trimestre | C7: IBNR Chain-Ladder | D7: IBNR BF | E7: IBNR Cape Cod | F7: BF−CL | G7: CC−CL | H7: BF % dif | I7: CC % dif
A8: AO01 | B8: Q4 2017 | C8: ='3_ChainLadder'!AD4 -> 0 | D8: ='4_BF'!H8 -> 0 | E8: ='5_CapeCod'!H8 -> 0 | F8: =D8-C8 -> 0 | G8: =E8-C8 -> 0 | H8: =IFERROR(F8/C8,"—") -> — | I8: =IFERROR(G8/C8,"—") -> —
A9: AO02 | B9: Q1 2018 | C9: ='3_ChainLadder'!AD5 -> 178192.62 | D9: ='4_BF'!H9 -> 175616.02 | E9: ='5_CapeCod'!H9 -> 175114.35 | F9: =D9-C9 -> -2576.6048 | G9: =E9-C9 -> -3078.2678 | H9: =IFERROR(F9/C9,"—") -> -0.014459661 | I9: =IFERROR(G9/C9,"—") -> -0.017274945
A10: AO03 | B10: Q2 2018 | C10: ='3_ChainLadder'!AD6 -> 350080.18 | D10: ='4_BF'!H10 -> 343664.97 | E10: ='5_CapeCod'!H10 -> 342683.26 | F10: =D10-C10 -> -6415.2142 | G10: =E10-C10 -> -7396.9241 | H10: =IFERROR(F10/C10,"—") -> -0.018324985 | I10: =IFERROR(G10/C10,"—") -> -0.021129228
